Workbook

Sheet 팀업무분장 상세(24.12.16)
A1: GS포천그린에너지 설비운영팀 업무분장 (상세)
A2: r 인력구성 : 팀장 외 31명(부장 2, 차장 4, 과장 9, 대리 8, 주임 9)
A3: r 주요업무 : 설비운영 및 발전효율 관리 | G3: (설비운영팀, 2024.12.16기준)
A4: 부서명 | C4: 담당자 | D4: 업무분야 | E4: 주요업무 | F4: 업무 세부내역 | G4: 부 담당자 | H4: 비 고
A5: 운영본부 | B5: 설비운영팀 | C5: 공진철 차장 | D5: 효율업무 총괄 (목표관리 및 원부재료, 용역사 관리) | E5: 효율파트 업무 총괄 | F5: • 효율파트 업무 총괄 현황관리 및 점검(운영현황 및 실적, 안전, 교육 등) | G5: 김형권 과장
E6: 운영목표 관리 | F6: • 팀내 주요 성과목표(KPI) 계획수립 및 실적관리 | G6: 김형권 과장
F7: • 년간운전계획 및 실적, 예산계획 수립
F8: • 통합경영시스템 실적관리
F9: • 운영본부 임원 회의자료 작성(경영계획, 분기실적자료, 자회사회의자료)
E10: 원부재료 운영 관리 | F10: • 유연탄 항차 탄종 연소성(사용 적정성) 분석 | G10: 김형권 과장
F11: • 연료(유연탄,Bio,유기성고형연료), 부재료(Ash,석회석,Lime 등) 입출고 계획 및 재고 관리 | H11: 보조 : 예비인력1
E12: 외주용역(연료설비, 특수미화원) 업무 관리 | F12: • 연료설비(Coal, Bio, 유기성고형연료) 운전 및 점검 관리 | G12: 송관석 주임 | H12: 보조 : 예비인력1
F13: • Ash(Fly Ash, Bed Ash, SDA Ash) 반출설비 운전 및 점검 관리 | H13: 보조 : 예비인력1
F14: • 특수미화원 역무 관리 | H14: 보조 : 예비인력1
F15: • 용역사 기성 내역 검토 및 관리 | H15: 보조 : 예비인력1
E16: T/G출력제어(KPX) | F16: • 전력거래소 및 비중앙발전기 출력제어운전 관련 업무 | G16: 김형권 과장
C17: 김형권 과장 | D17: 효율업무1 (설비운영∙운전 및 안전관리) | E17: 설비 운영관리 | F17: • 주간 운영실적(전력생산, 연료사용량 및 혼소율) 현황 관리(경영관리팀 공유) | G17: 공진철 차장
F18: • 유연탄 항차, Bio 및 유기성고형연료 입고 계획 관리
F19: • 유연탄, 혼소연료(Bio 등) 성적서 확인(REC 관련 매월 업체별 공인분석 성적서 관리)
F20: • Bio 및 유기성고형연료 혼소율 운전계획 대비 실적 관리(연료 발열량 등 고려)
F21: • 최적의 설비운영 및 원가절감 기술 검토
F22: • 보일러 및 터빈 성능분석 및 관리, 경제적 운전 방안 수립
F23: • 설비사고(공정사고 등) 및 주설비정지 원인 분석, 대응방안 검토 [공정사고 조사위원회 간사] | G23: (사고조사위원회 간사)
F24: • 연료원 다변화 및 혼소율 증대 관련 설비운전 영향 등 검토
E25: 설비 운전관리 | F25: • 각종 운전 Test 관리(연소 Test, 미연탄소분 관리, 설비 최적운전 조건 등) | G25: 공진철 차장
F26: • 기동, 정지 운전 계획 수립 및 검토(OH공사, 탄종변경 등)
F27: • 설비 고장정지 원인 분석 및 Trouble History 관리
E28: 통합문서(절차서) 관리 | F28: • 각종 운전절차서, 지침서 보완 및 개정 | G28: 공진철 차장
F29: • 설비운전 관련 참고 운전 Guide, Check List 양식 등 작성 및 관리
F30: • 무정지 운전 방안 검토(설비 정지 예상 상황 분석 및 조치방안, Risk 설비 조사 등)
E31: 안전관리 | F31: • 팀내 PSM 업무(변경관리, 가동전지침서, 안전운전지침서 등) | G31: 송관석 주임
F32: • 안전보건 교육(매월) 일지 관리, 아차사고 발굴 보고서 및 교육 관리
F33: • 소내설비 안전운전 위한 설비 점검, 합동안전점검 결과 조치사항 관리 | H33: 보조 : 예비인력1
F34: • 안전작업허가서 관리(정비부서, 연료설비 등 작업허가서 최종본 관리) | H34: 보조 : 예비인력1
C35: 송관석 주임 | D35: 효율업무2 (운영실적, 교육훈련, 행정∙구매관리) | E35: 운전자료 통계•Data 관리 | F35: • 운전기록 및 이력관리 (증기, 전기생산, 연료사용량, 약품 사용량 등) | G35: 김형권 과장
F36: • EP 운전정보시스템 운영정보 "일일운전현황(발전)", "일일 보고현황(효율)") Data 관리 | H36: 보조 : 예비인력2
F37: • 월간 운영실적 작성 및 관리(운전효율 등), 유관부서 공유(To.경영관리팀,운영지원팀,환경팀)
F38: • 전력판매량, 수전요금, 도시가스 요금 실적 관리
F39: • 연간 연료 사용량 등록 및 신고(한국에너지공단, 에너지관리자 업무)
F40: • 배출권 거래제 관련 업무(w. 경영관리팀)
...

Sheet 팀업무분장(25.09.01)
A1: GS포천그린에너지 설비운영팀 업무분장 (상세)
A2: r 인력구성 : 팀장 포함 총 33명(부장 2, 차장 4, 과장 8, 대리 8, 주임 11)
A3: r 주요업무 : 설비운영 및 발전효율 관리 | G3: (설비운영팀, 2025.11.01기준)
A4: 부서명 | C4: 담당자 | D4: 업무분야 | E4: 주요업무 | F4: 업무 세부내역 | G4: 부 담당자 | H4: 비 고
A5: 운영본부 | B5: 설비운영팀 | C5: 오현주 차장 | D5: 효율업무 총괄 (목표관리 및 원부재료, 용역사 관리) | E5: 효율파트 업무 총괄 | F5: • 효율파트 업무 총괄 현황관리 및 점검(운영현황 및 실적, 안전, 교육 등) | G5: 송관석 주임
E6: 운영목표 관리 | F6: • 팀내 주요 성과목표(KPI) 계획수립 및 실적관리 | G6: 송관석 주임
F7: • 년간운전계획 및 실적, 예산계획 수립
F8: • 통합경영시스템 실적관리
F9: • 운영본부 임원 회의자료 작성(경영계획, 분기실적자료, 자회사회의자료)
E10: 원부재료 운영 관리 | F10: • 유연탄 항차 탄종 연소성(사용 적정성) 분석 | G10: 송관석 주임 박태준 주임
F11: • 연료(유연탄,Bio,유기성고형연료), 부재료(Ash,석회석,Lime 등) 입출고 계획 및 재고 관리 | H11: (실무 박태준 지원)
E12: 외주용역(연료설비, 특수미화원) 업무 관리 | F12: • 연료설비(Coal, Bio, 유기성고형연료) 운전 및 점검 관리 | G12: 송관석 주임, 박태준 주임
F13: • Ash(Fly Ash, Bed Ash, SDA Ash) 반출설비 운전 및 점검 관리
F14: • 특수미화원 역무 관리 | H14: (신입 업무 지원)
F15: • 용역사 기성 내역 검토 및 관리
E16: 설비 운전관리 및 공정사고 관리 | F16: • 각종 운전 Test 관리(연소 Test, 미연탄소분 관리, 설비 최적운전 조건 등) | G16: 송관석 주임
F17: • 기동, 정지 운전 계획 수립 및 검토(OH공사, 탄종변경 등)
F18: • 설비 고장정지 원인 분석 및 Trouble History 관리
F19: • 설비사고(공정사고 등) 및 주설비정지 원인 분석, 대응방안 검토 [공정사고 조사위원회 간사]
E20: 통합문서(절차서) 관리 | F20: • 각종 운전절차서, 지침서 보완 및 개정 | G20: 송관석 주임
F21: • 설비운전 관련 참고 운전 Guide, Check List 양식 등 작성 및 관리
F22: • 무정지 운전 방안 검토(설비 정지 예상 상황 분석 및 조치방안, Risk 설비 조사 등)
E23: T/G출력제어(KPX) | F23: • 전력거래소 및 비중앙발전기 출력제어운전 관련 업무 | G23: 송관석 주임
C24: 송관석 주임 | D24: 효율업무1 (설비운영∙운전 및 안전관리) | E24: 설비 운영관리 | F24: • 주간 운영실적(전력생산, 연료사용량 및 혼소율) 현황 관리(경영관리팀 공유) | G24: 오현주 차장
F25: • 유연탄 항차, Bio 및 유기성고형연료 입고 계획 관리
F26: • 유연탄, 혼소연료(Bio 등) 성적서 확인(REC 관련 매월 업체별 공인분석 성적서 관리)
F27: • Bio 및 유기성고형연료 혼소율 운전계획 대비 실적 관리(연료 발열량 등 고려)
F28: • 최적의 설비운영 및 원가절감 기술 검토
F29: • 보일러 및 터빈 성능분석 및 관리, 경제적 운전 방안 수립
F30: • 연료원 다변화 및 혼소율 증대 관련 설비운전 영향 등 검토
E31: 안전관리 | F31: • 팀내 PSM 업무(변경관리, 가동전지침서, 안전운전지침서 등) | G31: (박태준 주임)
F32: • 안전보건 교육(매월) 일지 관리, 아차사고 발굴 보고서 및 교육 관리
F33: • 소내설비 안전운전 위한 설비 점검, 합동안전점검 결과 조치사항 관리
F34: • 안전작업허가서 관리(정비부서, 연료설비 등 작업허가서 최종본 관리)
C35: 송관석 주임 | D35: 효율업무2 (운영실적, 교육훈련, 행정∙구매관리) | E35: 운전자료 통계•Data 관리 | F35: • 운전기록 및 이력관리 (증기, 전기생산, 연료사용량, 약품 사용량 등) | G35: (충원시까지 오현주 차장, 박태준 주임)
F36: • EP 운전정보시스템 운영정보 "일일운전현황(발전)", "일일 보고현황(효율)") Data 관리
F37: • 월간 운영실적 작성 및 관리(운전효율 등), 유관부서 공유(To.경영관리팀,운영지원팀,환경팀)
F38: • 전력판매량, 수전요금, 도시가스 요금 실적 관리
F39: • 연간 연료 사용량 등록 및 신고(한국에너지공단, 에너지관리자 업무)
F40: • 배출권 거래제 관련 업무(w. 경영관리팀)
...

Sheet 팀업무분장 보고용(25.09.01)
A1: GS포천그린에너지 설비운영팀 업무분장
A2: r 인력구성 : 팀장 포함 총 32명(부장 2, 차장 4, 과장 8, 대리 8, 주임 10)
A3: r 주요업무 : 설비운영 및 발전효율 관리 | F3: (설비운영팀, 2025.11.01기준)
A4: 부서명 | B4: 담당자 | C4: 업무분야 | D4: 주요업무 | E4: 업무 세부내역 | F4: 부 담당자 | G4: 비 고
A5: 설비운영팀 | B5: 오현주 차장 | C5: 효율업무 총괄 (목표관리 및 원부재료, 용역사 관리) | D5: 효율파트 업무 총괄 | E5: • 효율파트 업무 총괄 현황관리 및 점검(운영현황 및 실적, 안전, 교육 등) | F5: 송관석 주임
D6: 운영목표 관리 | E6: • 팀내 주요 성과목표(KPI) 계획수립 및 실적관리 | F6: 송관석 주임
E7: • 년간운전계획 및 실적, 예산계획 수립
E8: • 통합경영시스템 실적관리
E9: • 운영본부 임원 회의자료 작성(경영계획, 분기실적자료, 자회사회의자료)
D10: 원부재료 운영 관리 | E10: • 유연탄 항차 탄종 연소성(사용 적정성) 분석 | F10: 송관석 주임 박태준 주임
E11: • 연료(유연탄,Bio,유기성고형연료), 부재료(Ash,석회석,Lime 등) 입출고 계획 및 재고 관리 | G11: (실무 박태준 지원)
D12: 외주용역(연료설비, 특수미화원) 업무 관리 | E12: • 연료설비(Coal, Bio, 유기성고형연료) 운전 및 점검 관리 | F12: 송관석 주임, 박태준 주임
E13: • Ash(Fly Ash, Bed Ash, SDA Ash) 반출설비 운전 및 점검 관리
E14: • 특수미화원 역무 관리 | G14: (신입 업무 지원)
E15: • 용역사 기성 내역 검토 및 관리
D16: 설비 운전관리 및 공정사고 관리 | E16: • 각종 운전 Test 관리(연소 Test, 미연탄소분 관리, 설비 최적운전 조건 등) | F16: 송관석 주임
E17: • 기동, 정지 운전 계획 수립 및 검토(OH공사, 탄종변경 등)
E18: • 설비 고장정지 원인 분석 및 Trouble History 관리
E19: • 설비사고(공정사고 등) 및 주설비정지 원인 분석, 대응방안 검토 [공정사고 조사위원회 간사]
D20: 통합문서(절차서) 관리 | E20: • 각종 운전절차서, 지침서 보완 및 개정 | F20: 송관석 주임
E21: • 설비운전 관련 참고 운전 Guide, Check List 양식 등 작성 및 관리
E22: • 무정지 운전 방안 검토(설비 정지 예상 상황 분석 및 조치방안, Risk 설비 조사 등)
D23: T/G출력제어(KPX) | E23: • 전력거래소 및 비중앙발전기 출력제어운전 관련 업무 | F23: 송관석 주임
B24: 송관석 주임 | C24: 효율업무1 (설비운영∙운전 및 안전관리) | D24: 설비 운영관리 | E24: • 주간 운영실적(전력생산, 연료사용량 및 혼소율) 현황 관리(경영관리팀 공유) | F24: 오현주 차장
E25: • 유연탄 항차, Bio 및 유기성고형연료 입고 계획 관리
E26: • 유연탄, 혼소연료(Bio 등) 성적서 확인(REC 관련 매월 업체별 공인분석 성적서 관리)
E27: • Bio 및 유기성고형연료 혼소율 운전계획 대비 실적 관리(연료 발열량 등 고려)
E28: • 최적의 설비운영 및 원가절감 기술 검토
E29: • 보일러 및 터빈 성능분석 및 관리, 경제적 운전 방안 수립
E30: • 연료원 다변화 및 혼소율 증대 관련 설비운전 영향 등 검토
D31: 안전관리 | E31: • 팀내 PSM 업무(변경관리, 가동전지침서, 안전운전지침서 등) | F31: (박태준 주임)
E32: • 안전보건 교육(매월) 일지 관리, 아차사고 발굴 보고서 및 교육 관리 | G32: (실무 박태준 지원)
E33: • 소내설비 안전운전 위한 설비 점검, 합동안전점검 결과 조치사항 관리
E34: • 안전작업허가서 관리(정비부서, 연료설비 등 작업허가서 최종본 관리)
B35: 송관석 주임 | C35: 효율업무2 (운영실적, 교육훈련, 행정∙구매관리) | D35: 운전자료 통계•Data 관리 | E35: • 운전기록 및 이력관리 (증기, 전기생산, 연료사용량, 약품 사용량 등) | F35: (충원시까지 오현주 차장, 박태준 주임)
E36: • EP 운전정보시스템 운영정보 "일일운전현황(발전)", "일일 보고현황(효율)") Data 관리 | G36: (실무 김덕용 지원)
E37: • 월간 운영실적 작성 및 관리(운전효율 등), 유관부서 공유(To.경영관리팀,운영지원팀,환경팀)
E38: • 전력판매량, 수전요금, 도시가스 요금 실적 관리
E39: • 연간 연료 사용량 등록 및 신고(한국에너지공단, 에너지관리자 업무)
E40: • 배출권 거래제 관련 업무(w. 경영관리팀)
...

Sheet 운전_업무분장(7)_old
B2: 업 무 분 장 표 (운전파트)
E4: 2022.02.14
B5: 구분 | C5: Position | D5: 담당 업무내용 | E5: 비 고
B6: 1 | C6: Part장 | D6: 1) 운전관리 - 발전 운전 현황 및 일일 운전 현황 보고 - 환경, 수질, 소방설비, 유해 위험설비, 회전기기 등 발전 및 열생산 설비 운전 총괄 - 열수요처 증기 공급상태 파악 및 안정적 증기공급 운전 조치 - Trouble Report, 운전절차서 등 검토 및 확인 - 일근 시간외 사업장 전체 설비 운전 관리(수용가 민원, 외주용역 운전 등) 2) 설비관리 및 안전관리 - 파트원 운전, 순찰 및 점검 등 업무 관리, 설비 청결 상태 관리 - T.M 및 B.M 즉각 대응 관리, 작업허가서 승인 및 작업 완료 관리 - 정비작업 전후 설비 안전점검 현황 관리 - 운전원 자체 정비 및 긴급 임시조치 작업, 정비원 돌발작업(BM)의 안전관리 3) 비상상황 대응 - 비상시 상황 보고 및 긴급 대응 조치 4) 교육 훈련 및 파트원 관리 - 통합 비상모의 훈련 및 월간 비상모의 훈련 주관 - 파트원 직무교육 주관 및 상위 보직 인력 육성 - 안전교육 및 설비사고 대응 훈련 - 파트원 애로사항 및 건의사항 수렴(상담)
B7: 2 | C7: TGO | D7: 1) Turbine & Generator설비 및 BOPp(HP, LP Bypass 등)설비 : 운전 및 기록관리 - TBN & Generator 출력 및 기록관리, BOP설비 기록관리 : Logging Data Sheet 작성 - 회전기기 교체 운전(월간 및 긴급 교체운전) - 설비 이상 징후 Monitoring(T.M 및 B.M 발행, 수질관리) - 기동∙정지 운전관리(절차서 수정) - 계절별 BOP 대응 운전(Cooling Tower 및 회전기기 관리) 2) 공정용 증기(HP 및 LP Process Steam) 공급 - 압력 및 온도 기록 관리 - 비상 상황 발생시 공정 증기 안정 공급 3) Aux. Boiler 운전 관리 - 정지 시 만수보존 관리 - Main BLR 및 TBN 정지 시 Aux. BLR 기동(기동 중 기록 관리) 4) ECMS 설비운전 - 차단기 원격 조작(전기팀 입회 및 사전 확인) - Alarm 및 Event 상시 확인 5) Package System 및 HVAC 설비 운전 - Plant Air Compressor 및 Sump Pump(TBN & BOP Building) 운전 관리 - 주제어동, 냉각수펌프동, 터빈동, 보조보일러동 HVAC System 관리 6) 태양광 발전 Monitoring System - 운전 상태 점검 및 일/월 Data 적산 관리, Alarm 등의 특이사항 관리 | E7: 1) Aux.BLR 운전은 모든 운전원이 기동∙정지 숙지 (총 관리는 TGO) 2) BOPp: 보일러분야를 제외한 발전계통의 BOP 설비(급∙복수 및 냉각수계통, Plant Air Comp., 전기실, SWGR, GIS, TR, 비상발전기, Service/Potable water설비 등)
B8: 3 | C8: BCO1 | D8: 1) No.1 CFBC Boiler & BOPb, 정압기실, Fly Ash Silo 설비 : 운전 및 기록관리 - 회전기기 교체운전 (교체운전 Check List 작성) - 계절별 대응운전 (Steam Coil Air Heater, PA,SA Inler Damper 조절) - Fuel(Coal&Bio) Feeding System Trouble 대처 및 연료 혼소율 조정 운전 - 보일러 기동 및 정지 운전관리, 운전 절차서 수정 및 보완 - 부재료 사용량 관리 2) 설비 예방관리 Monitoring 및 최적운전 관리, 고장 설비 TM 발행 - Service GAS(N2) 설비(Check List, Log Sheet 작성) 포함 3) TMS 환경 기준치 이내운전 관리(Sox, Nox, Dust) 4) TBN/GEN 운전관리 지원(Aux' Boiler 가동시) 5) 팀내 필요 교육 수행(파트별) - 비상모의훈련, PSM교육, 아차사고사례 교육, 자체직무교육 등 6) TM 회의 자료 작성(일일발전운전현황) 및 일일 Boiler 적산 작성 (내부 보고용) | E8: 1) BOPb: 보일러 부속설비(Blower류, 연료 및 부재료 계통, 배가스 환경설비 등)
B9: 4 | C9: BCO2 | D9: 1) No.2 CFBC Boiler & BOPb, Ash Air Comp. : 운전 및 기록관리 - 회전기기 교체운전(교체운전 Check List 작성, Ash Comp. 교체운전 1회/일) - 계절별 대응운전 (Steam Coil Air Heater, PA,SA Inler Damper 조절) - Fuel(Coal&Bio) Feeding System Trouble 대처 및 연료 혼소율 조정 운전 - 보일러 기동 및 정지 운전관리, 운전 절차서 수정 및 보완 - 부재료 사용량 관리 2) 설비 예방관리 Monitoring 및 최적운전 관리, 고장 설비 TM 발행 3) TMS 환경 기준치 이내운전 관리(SOx, NOx, Dust) 4) 수처리 및 연료취급설비(외주용역) 운전 업무지원(운전 협조) 5) 팀내 필요 교육 수행(파트별) - 안전교육(일지관리), 비상모의훈련, PSM교육, 아차사고사례 교육, 자체직무교육 등 6) TM 회의 자료 작성(일일발전운전현황) 및 일일 Boiler 적산 작성 (내부 보고용)
B10: 5 | C10: TO | D10: 1) TBN & BOP, Aux Boiler, BOPp : 현장운전, Log Sheet 기록 및 순찰 점검(소방 포함) - 설비 및 안전 위험사항 조기발굴 및 임시조치 2) CFBC Boiler 정지시 열공급 위한 Aux. Boiler 운전 지원(TGO 지원) 3) T.M 발행 및 보수 작업 관리(Tag관리 등) 4) 설비별 각 월간점검, 주간점검 및 교체운전(현장) 관리 - 소화기 점검(월간), TBN Hanger점검(월간), 비상발전기 점검(월간),NG사용량점검(월말) 5) TBN 증기계통 및 소내 Process Steam Line 응축수 관리(Drain 및 Trap 관리) 6) 설비 비상사고 현장 조치 및 사고원인 파악 7) TBN동 현장 청결관리, 주제어동 지하 순찰(Sump운전 상태 및 Cable Room 확인)
B11: 6 | C11: BO1 (1호기 Boiler) | D11: 1) No.1 CFBC Boiler & BOPb, 정압기실, Fly Ash Silo설비 : 현장운전, Log Sheet기록 및 순찰 점검(소방 포함) - 설비 및 안전 위험사항 조기발굴 및 임시조치 2) T.M 발행 및 보수 작업 관리(Tag관리 등) 3) 설비별 각 월간점검, 주간점검 및 교체운전(현장) 관리(설비 점검사항 및 작성 주기표 참조) - 소화기 점검(월간), 고압가스(CO2) 저정시설 점검(주간), 보일러 Hanger 점검(월간) Sootblower(주간), Coal Sampling(월1회), Fly Ash Sampling(주1회) 등 4) 설비 비상사고 현장 조치 및 사고원인 파악 5) 동절기, 해빙기, 우기시 현장 예방점검 6) BLR동 현장 청결관리
B12: 7 | C12: BO2 (2호기 Boiler) | D12: 1) No.2 CFBC Boiler & BOPb, Ash Comp. : 현장운전, Log Sheet기록 및 순찰 점검(소방 포함) - 설비 및 안전 위험사항 조기발굴 및 임시조치 2) T.M 발행 및 보수 작업 관리(Tag관리 등) 3) 설비별 각 월간점검, 주간점검 및 교체운전(현장) 관리(설비 점검사항 및 작성 주기표 참조) - 소화기 점검(월간), 고압가스(CO2) 저정시설 점검(주간), 보일러 Hanger 점검(월간) Sootblower(주간), Coal Sampling(월1회), Fly Ash Sampling(주1회) 등 4) 설비 비상사고 현장 조치 및 사고원인 파악 5) 동절기, 해빙기, 우기시 현장 예방점검 6) BLR동 현장 청결관리
B13: ※ 특기사항 : 1. 운전파트 지시사항, 설비운전중 비상상황 업무, 효율파트 역무 관련 운전파트 협조사항, 명시되지 않은 기타 역무 등은 각 파트장이 필요에 따라 파트원 역무 별도 지시하여 수행. 2. Local 운전원(TO, BO1, BO2)는 업무 상황 및 안전을 고려하여 따라 상호 지원 또는 협업하여 업무 수행

Sheet 팀업무분장(26.01.15)
A1: GS포천그린에너지 설비운영팀 업무분장
A2: r 인력구성 : 팀장 포함 총 33명(부장 3, 차장 6, 과장 8, 대리 6, 주임 10)
A3: r 주요업무 : 설비운영 및 발전효율 관리 | F3: (설비운영팀, 2026.05.15기준)
A4: 부서명 | B4: 담당자 | C4: 업무분야 | D4: 주요업무 | E4: 업무 세부내역 | F4: 부 담당자 | G4: 비 고
A5: 설비운영팀 | B5: 오현주 부장 | C5: 효율업무 총괄 (목표관리 및 원부재료, 용역사 관리) | D5: 효율파트 업무 총괄 | E5: • 효율업무1&2 담당자 업무 현황 총괄 점검 및 관리
A6: / 효율파트 | E6: - 년간 운영계획 목표 대비 실적, Catch-up 현황 점검
E7: - 설비운영 현황 및 실적, 원부재료 운영관리, 운전관리 및 설비고장 관리 현황 점검
E8: - 운전절차서, 안전관리, 교육훈련 현황 점검 및 관리 등등
D9: 외주용역(연료설비, 특수미화원) 업무 관리 | E9: • 연료설비(Coal, Bio, 유기성고형연료) 운전 및 점검 관리, 현장 순찰 점검 | F9: 이성진 과장 (송관석 대리)
E10: • Ash(Fly Ash, Bed Ash, SDA Ash) 반출설비 운전 및 점검 관리, 현장 순찰 점검 | G10: 전민정 지원
E11: • 특수미화원 역무 관리, 굴삭기 및 집게차 등 안전작업 관리
E12: • 용역업무(연료설비 운전, 신호수, 특수미화원) 안전관리 및 운전지침서 관리
E13: • 용역사 기성 내역 검토, 요청사항 및 미비사항 점검 관리
D14: 설비 현장순잘 점검, 관리 | E14: • 주요 TM사항 및 설비 정상화 상태 점검, 관리 | F14: 이성진 과장
E15: • 주설비 및 부대설비 설비점검 현장순찰 및 안전점검
D16: T/G출력제어(KPX) | E16: • 전력거래소 및 비중앙발전기 출력제어운전 관련 업무 | F16: 이성진 과장
B17: 이성진 과장 | C17: 효율업무1 (설비운영∙운전 및 안전관리) | D17: 운영목표 관리 | E17: • 팀내 주요 성과목표(KPI) 계획수립, 실적 및 Catch-up 관리 | F17: 송관석 대리 (오현주 부장)
E18: • 년간운전계획 및 실적, 예산계획 수립
D19: 설비 운영관리 | E19: • 주간 운영실적(전력생산, 연료사용량 및 혼소율) 현황 관리(경영관리팀 공유) | F19: 송관석 대리
E20: • Bio 및 유기성고형연료 혼소율 운전계획 대비 실적 관리(연료 발열량 등 고려)
E21: • 최적의 설비운영 및 원가절감 기술 검토
E22: • 보일러 및 터빈 성능분석 및 관리, 경제적 운전 방안 수립
E23: • 연료원 다변화 및 혼소율 증대 관련 설비운전 영향 등 검토
D24: 원부재료 운영관리 | E24: • 유연탄 항차 탄종 연소성(사용 적정성) 분석 | F24: 송관석 대리
E25: • 원재료(유연탄, Bio, 유기성고형연료 등) 및 부재료, Ash 입출고 계획 및 재고 관리 | G25: 전민정 지원
E26: • 유연탄, 혼소연료(Bio 등) 성적서 확인(REC 관련 매월 업체별 공인분석 성적서 관리)
D27: 설비 운전관리, 공정∙설비사고 관리 | E27: • 각종 운전 Test 관리(연소 Test, 미연탄소분 관리, 설비 최적운전 조건 등) | F27: 송관석 대리
E28: • 기동, 정지 운전 계획 수립 및 검토(OH공사, 탄종변경 등)
E29: • 설비 고장정지 원인 분석 및 Trouble History 관리
E30: • 공정사고∙설비사고 및 주설비정지 원인 분석, 대응방안 검토 [공정,설비사고 조사 간사]
E31: • 주요 설비사고(공정사고, 주설비 정지 등) 상황속보 작성
D32: 통합문서(운전절차서) 관리 | E32: • 각종 운전절차서, 지침서 보완 및 개정 | F32: 송관석 대리
E33: • 설비운전 관련 참고 운전 Guide, Check List 양식 등 작성 및 관리
E34: • 무정지 운전 방안 검토(설비 정지 예상 상황 분석 및 조치방안, Risk 설비 조사 등)
B35: 송관석 주임 | C35: 효율업무2 (운영실적, 교육훈련, 행정∙구매관리) | D35: 운전 통계•Data 관리 | E35: • 운전기록 및 이력관리 (증기, 전기생산, 연료사용량, 약품 사용량 등) | F35: 이성진 과장
E36: • EP 운전정보시스템 운영정보 "일일운전현황(발전)", "일일 보고현황(효율)") Data 관리 | G36: 전민정 지원(실무)
E37: • 월간 운영실적 작성 및 관리(운전효율 등), 유관부서 공유(To.경영관리팀,운영지원팀,환경팀)
E38: • 전력판매량, 수전요금, 도시가스 요금 실적 관리
E39: • 연간 연료 사용량 등록 및 신고(한국에너지공단, 에너지관리자 업무)
E40: • 배출권 거래제 관련 업무(w. 경영관리팀)
...

Sheet 주요Issue
A1: 설비운영팀 주요 Issue 업무 지시 및 진행현황
A3: [팀장 직접 수정 관리] | H3: 2026.05월 기준
A4: No. | B4: 주관분야 | C4: Issue 사항 | D4: Issue 시기 | E4: 담당(정,부) | F4: 진행현황 | G4: 처리결과 | H4: 비고
B5: 효율+운전 | C5: 바이오 혼소량 증대에 따른 배가스 CO 농도 감소위한 운전조건 Test 가능한지? => (설비운영팀) 배가스계통에 있는 CO 계측기 정상화 되어야 운전조건에 따른 CO 농도변화 Test 가능. 제어팀에 CO 계측기 정상화 가능성 우선 요청 예정 | D5: '25.10.28(부문장님)
B6: 효율+운전 | C6: 운전원 Logging일지 작성건 Works 등을 이용하여 Paperless로 작성 및 관리토록 개선 요망 | D6: '25.11.07(대표님) | E6: 송관석,박태준+운전
B7: 효율 | C7: 월간운영실적 매월 1일차에 작성완료하여 보고 가능토록 업무개선 요망. 필요시 가결산자료 추정하여 적용 등 | D7: '25.11.07(부문장님) | E7: 송관석
B8: 효율 | C8: 고압가스(CO2) 안전관리업무는 2026.1.1일자 기준으로 설비운영팀에서 안전팀으로 이관 | D8: '25.11.11(부문장님) | E8: ` | G8: 완료(26.1.6이관)
B9: 운전 | C9: 2026.1.1(목)부터 주보일러 SCAH 운전기준 110도에서 100도로 하향하여 운전 요망 | D9: '25.12.12(부문장님) | E9: 운전파트 | G9: 완료(26.1.1시행)
B10: 효율 | C10: EP 실시간운전정보시스템 Data 및 그래픽 오류 또는 수정, 보완사항 List-up | D10: '26.1.15(팀장) | E10: 이성진+운전파트 | F10: 진행중(전기제어팀에 List 제공)
B11: 운전 | C11: 2026년 대기오염물질 총량 관련 Sox는 17.5ppm으로 결정되어, 주보일러 Stack Sox 평균 배출농도 15ppm(6)으로 운전관리 요망 | D11: '26.1.16(환경팀) | E11: 운전파트 | G11: 완료(시행중)
B12: 효율 | C12: 주요설비 긴급상황 대처(Tube 파열, Turbo Air Comp. 정지 등등) 및 안전운전 Guide 취합 작성
B13: 효율 | C13: 고장 및 정지사례집 2025년 말까지 History 추가 Up date
B14: 효율 | C14: 꼬리표(Tag) 및 Interlock 해제/복귀 관리 철저 요망. 꼬리표, Interlock 운용지침서 숙지후 지침서에 따라 관리 요망. Tag 발행시 Tag no. 기록, 회수된 Tag는 1년간 보존 요망 | E14: 운전파트+송관석
B15: 운전(3P) | C15: 운전 3파트에 설비, 밸브 명칭 입력시 위치 확인할 수 있는 네비게이터 작성하여 임원회의 발표할 수 있도록 준비 요망 | D15: '26.1.23(부문장님) | E15: 3파트+운전,효율
B16: 효율 | C16: 교대파트 휴가 관리 사이트 개설 | D16: 자율 | E16: 송관석 | F16: '26.2.3 메일 공유(설비운영팀+이현정(경관) | G16: 완료(26.2.3)
B17: 효율 | C17: 송관석대리 광물 탄산화 담당지 지정 (GS건설 탈탄소 Solution 제안건 관려) | D17: '26.2.3(부문장님) | E17: 송관석 | F17: '26.2.3(화) 부문장님 지정
B18: 운전 | C18: 터빈 감속기 기어 교체 정비시까지 주말등 SMP가 전기생산원가 이하이더라도 터빈발전기 감발없이 정상부하운전 요망 | D18: '26.5.15(부문장님) | E18: 파트장+TGO | G18: 즉시 시행
B19: 운전 | C19: 유기성고형연료 운전역무 조정 : ∙ 하역 및 이송설비(하역~신설Silo~기존 Silo) 운전업무 주담당자 BCO1 및 BO1, 부담당자 BCO2 및 BO2 ∙ 유기성고형연료 공급설비(기존설비 Silo~보일러 연소실)는 1,2호기 운전원(제어실, 현장) 각각 담당 | D19: '26.5.15(팀장) | E19: 운전파트 | G19: 즉시 시행
B20: 운전 | C20: 1,2호기 Bed Ash 배출주기 호기별 4회/일에서 6회/일로 증대(호기별 1회 배출량은 2톤이상 유지), 필요시 추가 배출 | D20: '26.5.20(팀장) | E20: 파트장+BCO | G20: 즉시 시행

Sheet 설비운영팀 26년 월별업무
A1: 설비운영팀 2026년 월별 업무 계획
A2: 구 분 | B2: 1월 | D2: 2월 | F2: 3월 | H2: 4월 | J2: 5월 | L2: 6월 | N2: 7월 | P2: 8월 | R2: 9월 | T2: 10월 | V2: 11월 | X2: 12월 | Z2: 비고
B3: 주요 업무 | C3: 일정 | D3: 주요 업무 | E3: 일정 | F3: 주요 업무 | G3: 일정 | H3: 주요 업무 | I3: 일정 | J3: 주요 업무 | K3: 일정 | L3: 주요 업무 | M3: 일정 | N3: 주요 업무 | O3: 일정 | P3: 주요 업무 | Q3: 일정 | R3: 주요 업무 | S3: 일정 | T3: 주요 업무 | U3: 일정 | V3: 주요 업무 | W3: 일정 | X3: 주요 업무 | Y3: 일정
A4: 운영 업무 (효율) | B4: - 25년말 원재료(유연탄, 바이오 등) 재고실사결과 송부(재무회계팀) | C4: 1/5 | F4: - PSM심사 준비 | H4: - 1분기 운영 실적 Data 보고(터빈 이용률 및 혼소율) | I4: 4/7 | J4: - OH공사 기동운전계획(내화물건조, 수질개선, 유동사(신사)입고 등) | K4: 5/15,5/22 | L4: - 장마철, 하절기 집중호우 대비 양수펌프 현황 점검 | M4: 6/2(첫주) | N4: - 2분기 운영 실적 Data 보고(터빈 이용률 및 혼소율) | O4: 7/7 | P4: - 차년도 경영계획 운전Data작성(w.경영관리팀) | Q4: 8/11 | R4: - 차기년도 팀 예산안, 중점추진과제 등 준비 | S4: 9/8 | T4: - 3분기 운영 실적 Data 보고(터빈 이용률 및 혼소율) | U4: 10/13 | V4: - 동절기 열공급시설(열원시설) 안전점검(한국에너지공단, 안전팀 송부) | W4: 11/10 | X4: - 4분기 및 년간 운영실적 Data 보고 (터빈 이용률 및 혼소율) | Y4: 12/28
B5: - 2025년 에너지사용량 신고 | C5: 1/22 | D5: - SDA Hopper Ash 완전배출(2,5,8,11월) | E5: 4주차(화) | H5: - OH 공사대비 정지운전(Shut Down Curve 등) 계획(2주전) | I5: 4/15 | J5: - 정지후 보일러 등 설비상태 점검 | K5: OH기간 | N5: - 팀원 하계휴가 계획 파악(6월말~7월초) | O5: 7/2 | P5: - SDA Hopper Ash 완전배출(2,5,8,11월) | Q5: 4주차(화) | R5: - 운영실적 및 예상치 작성(년간 실적자료) | S5: 9/8 | V5: - 연료설비 Mist Spray Drain(동결예방) | W5: 11/10 | X5: - 년말 원재료(유연탄, 바이오 등) 실제/장부 재고 점검(혼소율 연계) | Y5: 12/22
B6: - PSM문서(운전절차서) 적합성검토 | C6: 1/8 | D6: - 2026년 KPI, Action Plan 제출 | E6: 2/15 ? | H6: - OH공사시 정지중 작업사항 List 재확인 (정비부서 제공, 추가작업 지시건)(3주전) | I6: 4/10 | J6: - Lime Solution Tank 및 Feed Tank 청소 | K6: OH기간 | R6: - 추석명절 연휴기간 운영계획(비상대기, 원부재료, Ash) | S6: 9/18 | V6: - SDA Hopper Ash 완전배출(2,5,8,11월) | W6: 4주차(화) | X6: - PSM 절차서 적합성 사전 검토 | Y6: 12/23 ?
B7: -2026년 Bio, 유기성고형연료 사용량 계획 | D7: - 설명절연휴기간 운영계획(원부재료, Ash, 근무자) | E7: 2/11 | H7: - OH공사 정지시 주요 Motor 정지일정 검토(w전기,기계)(2주전) | I7: 4/16 | J7: - 건물바닥(본관 HVAC, Air Comp., MCWP Room, Aux. Boiler) 고압세척 | K7: OH기간 | R7: - 추석연휴 전후 열원시설 특별안전점검(w.안전팀) | S7: 9/23, 9/29 | X7: - Coal 하역계통 수증기, 상하역계통 Duct Drain 관리 | Y7: 12/1
B8: - 25년 통합비상모의훈련 계획, 직무교육계획 보고 | C8: 1/20 | D8: - 설연휴 전후 열원시설 특별안전점검(w.안전팀) | E8: 2/13, 2/19 | H8: - OH공사기간 운전파트 인력운용계획(3주전) | I8: 4/10 | J8: - OH: BLR Air Comp.정지,습분등유지관리 | K8: OH기간 | X8: - 동절기 Coal Silo 배출탄 동결 예방 운전(RRDM 일일 교차 운전) | Y8: 12/1
B9: - 2026년 KPI초안, Action Plan 수립 | D9: - 2026년 운전 Test 계획 수립
B10: '- OH공사시 정지중 작업사항 List-up 1차(정비부서 제공, 3~4개월전) | C10: 1/12 | F10: `
B11: - 2026년 운전 Test 계획 초안 검토
B13: - 주간 원부재료, Ash 배차 소요계획(to.운영지원팀) | C13: 매주목 | D13: - 주간 원부재료, Ash 배차 소요계획(to.운영지원팀) | F13: - 주간 원부재료, Ash 배차 소요계획(to.운영지원팀) | H13: - 주간 원부재료, Ash 배차 소요계획(to.운영지원팀) | J13: - 주간 원부재료, Ash 배차 소요계획(to.운영지원팀) | L13: - 주간 원부재료, Ash 배차 소요계획(to.운영지원팀) | N13: - 주간 원부재료, Ash 배차 소요계획(to.운영지원팀) | P13: - 주간 원부재료, Ash 배차 소요계획(to.운영지원팀) | R13: - 주간 원부재료, Ash 배차 소요계획(to.운영지원팀) | T13: - 주간 원부재료, Ash 배차 소요계획(to.운영지원팀) | V13: - 주간 원부재료, Ash 배차 소요계획(to.운영지원팀) | X13: - 주간 원부재료, Ash 배차 소요계획(to.운영지원팀)
B14: - 주간 운영실적(to.경영관리팀) | C14: 매주화 | D14: - 주간 운영실적(to.경영관리팀) | F14: - 주간 운영실적(to.경영관리팀) | H14: - 주간 운영실적(to.경영관리팀) | J14: - 주간 운영실적(to.경영관리팀) | L14: - 주간 운영실적(to.경영관리팀) | N14: - 주간 운영실적(to.경영관리팀) | P14: - 주간 운영실적(to.경영관리팀) | R14: - 주간 운영실적(to.경영관리팀) | T14: - 주간 운영실적(to.경영관리팀) | V14: - 주간 운영실적(to.경영관리팀) | X14: - 주간 운영실적(to.경영관리팀)
B15: - 월간(전월) 운영실적 보고 | C15: 월초 W.D 5일이내 | D15: - 월간(전월) 운영실적 보고 | F15: - 월간(전월) 운영실적 보고 | H15: - 월간(전월) 운영실적 보고 | J15: - 월간(전월) 운영실적 보고 | L15: - 월간(전월) 운영실적 보고 | N15: - 월간(전월) 운영실적 보고 | P15: - 월간(전월) 운영실적 보고 | R15: - 월간(전월) 운영실적 보고 | T15: - 월간(전월) 운영실적 보고 | V15: - 월간(전월) 운영실적 보고 | X15: - 월간(전월) 운영실적 보고
B16: - 전월 설비운영현황(to.재무회계,cc운영지원) | C16: 월초 W.D3일이내 | D16: - 전월 설비운영현황(to.재무회계,cc운영지원) | F16: - 전월 설비운영현황(to.재무회계,cc운영지원) | H16: - 전월 설비운영현황(to.재무회계,cc운영지원) | J16: - 전월 설비운영현황(to.재무회계,cc운영지원) | L16: - 전월 설비운영현황(to.재무회계,cc운영지원) | N16: - 전월 설비운영현황(to.재무회계,cc운영지원) | P16: - 전월 설비운영현황(to.재무회계,cc운영지원) | R16: - 전월 설비운영현황(to.재무회계,cc운영지원) | T16: - 전월 설비운영현황(to.재무회계,cc운영지원) | V16: - 전월 설비운영현황(to.재무회계,cc운영지원) | X16: - 전월 설비운영현황(to.재무회계,cc운영지원)
B17: - 전월 연료사용일지&우드칩사용실적(to.환경팀) | C17: 월초 W.D 5일이내 | D17: - 전월 연료사용일지 & 우드칩 사용실적(to.환경팀) | F17: - 전월 연료사용일지 & 우드칩 사용실적(to.환경팀) | H17: - 전월 연료사용일지 & 우드칩 사용실적(to.환경팀) | J17: - 전월 연료사용일지 & 우드칩 사용실적(to.환경팀) | L17: - 전월 연료사용일지 & 우드칩 사용실적(to.환경팀) | N17: - 전월 연료사용일지 & 우드칩 사용실적(to.환경팀) | P17: - 전월 연료사용일지 & 우드칩 사용실적(to.환경팀) | R17: - 전월 연료사용일지 & 우드칩 사용실적(to.환경팀) | T17: - 전월 연료사용일지 & 우드칩 사용실적(to.환경팀) | V17: - 전월 연료사용일지 & 우드칩 사용실적(to.환경팀) | X17: - 전월 연료사용일지 & 우드칩 사용실적(to.환경팀)
B18: - 월간 REC 발급용 발전운영실적 & 연료관리대장(to.경영관리팀) | C18: 매월 25일이내(전후) | D18: - 월간 REC 발급용 발전운영실적 & 연료관리대장(to.경영관리팀) | F18: - 월간 REC 발급용 발전운영실적 & 연료관리대장(to.경영관리팀) | H18: - 월간 REC 발급용 발전운영실적 & 연료관리대장(to.경영관리팀) | J18: - 월간 REC 발급용 발전운영실적 & 연료관리대장(to.경영관리팀) | L18: - 월간 REC 발급용 발전운영실적 & 연료관리대장(to.경영관리팀) | N18: - 월간 REC 발급용 발전운영실적 & 연료관리대장(to.경영관리팀) | P18: - 월간 REC 발급용 발전운영실적 & 연료관리대장(to.경영관리팀) | R18: - 월간 REC 발급용 발전운영실적 & 연료관리대장(to.경영관리팀) | T18: - 월간 REC 발급용 발전운영실적 & 연료관리대장(to.경영관리팀) | V18: - 월간 REC 발급용 발전운영실적 & 연료관리대장(to.경영관리팀) | X18: - 월간 REC 발급용 발전운영실적 & 연료관리대장(to.경영관리팀)
B19: - 전월 수전요금 검토 및 품의 | C19: 월초(WD7차) | D19: - 전월 수전요금 검토 및 품의 | F19: - 전월 수전요금 검토 및 품의 | H19: - 전월 수전요금 검토 및 품의 | J19: - 전월 수전요금 검토 및 품의 | L19: - 전월 수전요금 검토 및 품의 | N19: - 전월 수전요금 검토 및 품의 | P19: - 전월 수전요금 검토 및 품의 | R19: - 전월 수전요금 검토 및 품의 | T19: - 전월 수전요금 검토 및 품의 | V19: - 전월 수전요금 검토 및 품의 | X19: - 전월 수전요금 검토 및 품의
B20: - 당월 연료운전팀 용역기성 검토,보고 | C20: 매월26~29 | D20: - 당월 연료운전팀 용역기성 실적검토,보고 | F20: - 당월 연료운전팀 용역기성 실적검토,보고 | H20: - 당월 연료운전팀 용역기성 실적검토,보고 | J20: - 당월 연료운전팀 용역기성 실적검토,보고 | L20: - 당월 연료운전팀 용역기성 실적검토,보고 | N20: - 당월 연료운전팀 용역기성 실적검토,보고 | P20: - 당월 연료운전팀 용역기성 실적검토,보고 | R20: - 당월 연료운전팀 용역기성 실적검토,보고 | T20: - 당월 연료운전팀 용역기성 실적검토,보고 | V20: - 당월 연료운전팀 용역기성 실적검토,보고 | X20: - 당월 연료운전팀 용역기성 실적검토,보고
B21: - EP 운영정보 일일현황(발전, 효율) 확인 | C21: 수시 | D21: - EP 운영정보 일일현황(발전, 효율) 확인 | F21: - EP 운영정보 일일현황(발전, 효율) 확인 | H21: - EP 운영정보 일일현황(발전, 효율) 확인 | J21: - EP 운영정보 일일현황(발전, 효율) 확인 | L21: - EP 운영정보 일일현황(발전, 효율) 확인 | N21: - EP 운영정보 일일현황(발전, 효율) 확인 | P21: - EP 운영정보 일일현황(발전, 효율) 확인 | R21: - EP 운영정보 일일현황(발전, 효율) 확인 | T21: - EP 운영정보 일일현황(발전, 효율) 확인 | V21: - EP 운영정보 일일현황(발전, 효율) 확인 | X21: - EP 운영정보 일일현황(발전, 효율) 확인
B22: - Fly Ash 미연탄소분 검토,관리(주단위 Trend) | C22: 매월10일전후(전월4주실적+계획) | D22: - Fly Ash 미연탄소분 검토,관리(주단위 Trend) | F22: - Fly Ash 미연탄소분 검토,관리(주단위 Trend) | H22: - Fly Ash 미연탄소분 검토,관리(주단위 Trend) | J22: - Fly Ash 미연탄소분 검토,관리(주단위 Trend) | L22: - Fly Ash 미연탄소분 검토,관리(주단위 Trend) | N22: - Fly Ash 미연탄소분 검토,관리(주단위 Trend) | P22: - Fly Ash 미연탄소분 검토,관리(주단위 Trend) | R22: - Fly Ash 미연탄소분 검토,관리(주단위 Trend) | T22: - Fly Ash 미연탄소분 검토,관리(주단위 Trend) | V22: - Fly Ash 미연탄소분 검토,관리(주단위 Trend) | X22: - Fly Ash 미연탄소분 검토,관리(주단위 Trend)
B23: - 전월 교대근무 정산자료(휴가)(To.경관) | C23: 월초 WD 1일 | D23: - 전월 교대근무 정산자료(휴가)(To.경관) | F23: - 전월 교대근무 정산자료(휴가)(To.경관) | H23: - 전월 교대근무 정산자료(휴가)(To.경관) | J23: - 전월 교대근무 정산자료(휴가)(To.경관) | L23: - 전월 교대근무 정산자료(휴가)(To.경관) | N23: - 전월 교대근무 정산자료(휴가)(To.경관) | P23: - 전월 교대근무 정산자료(휴가)(To.경관) | R23: - 전월 교대근무 정산자료(휴가)(To.경관) | T23: - 전월 교대근무 정산자료(휴가)(To.경관) | V23: - 전월 교대근무 정산자료(휴가)(To.경관) | X23: - 전월 교대근무 정산자료(휴가)(To.경관)
A25: 설비 운전, 점검 (운전) | B25: - 비상대응 모의훈련(매월, 파트별) | D25: - 비상대응 모의훈련(매월, 파트별) | F25: - 비상대응 모의훈련(매월, 파트별) | H25: - 비상대응 모의훈련(매월, 파트별) | J25: - 비상대응 모의훈련(매월, 파트별) | L25: - 비상대응 모의훈련(매월, 파트별) | N25: - 비상대응 모의훈련(매월, 파트별) | P25: - 비상대응 모의훈련(매월, 파트별) | R25: - 비상대응 모의훈련(매월, 파트별) | T25: - 비상대응 모의훈련(매월, 파트별) | V25: - 비상대응 모의훈련(매월, 파트별) | X25: - 비상대응 모의훈련(매월, 파트별)
B26: - BLR동 거미줄 제거, 터빈동 Floor청소 | C26: 2주차(금~일) | D26: - BLR동 거미줄 제거, 터빈동 Floor청소 | F26: - BLR동 거미줄 제거, 터빈동 Floor청소 | H26: - BLR동 거미줄 제거, 터빈동 Floor청소 | J26: - BLR동 거미줄 제거, 터빈동 Floor청소 | L26: - BLR동 거미줄 제거, 터빈동 Floor청소 | N26: - BLR동 거미줄 제거, 터빈동 Floor청소 | P26: - BLR동 거미줄 제거, 터빈동 Floor청소 | R26: - BLR동 거미줄 제거, 터빈동 Floor청소 | T26: - BLR동 거미줄 제거, 터빈동 Floor청소 | V26: - BLR동 거미줄 제거, 터빈동 Floor청소 | X26: - BLR동 거미줄 제거, 터빈동 Floor청소
D27: - 1/4분기 통합비상모의훈련(3P, 비상1) | E27: 2/24(화) | F27: - 건물 SUH 정지, 동결방지용 백열등 소등 | G27: 3/20 | H27: - 보조보일러 4호기 가동전 점검 (OH공사기간 기동시)(3일전) | I27: 4/29 | J27: - 각종 Valve, Damper류 작동 Test(OH공사 협조운전) | K27: 5/3 | L27: - 2/4분기 통합비상모의훈련(4P, 비상2) | M27: 6/11(목) | P27: - 3/4분기 통합비상모의훈련(1P, 비상4) | Q27: 8/21(금) | R27: '- 고압가스(CO2) 방출 Test(분기) | T27: - 동절기 대비 동파방지 점검(천막,보온,Heat Tracing) | U27: 10/13 | V27: - 4/4분기 통합비상모의훈련(2P, 비상3) | W27: 11/13(금) | X27: - 보조보일러 Eco. Tube M/H 개방(동파방지) | Y27: 12/1
F28: - 옥외 펌프류(정지설비) 및 Eye Washer 동결방지 Drain Close | G28: 3/20 | H28: - Demi. Pump Room 하부천막 해체 | I28: 4/11 | J28: - OH공사 관련 Tag 발행 및 회수 | K28: OH기간 | L28: - 장마철 대비 침수 예상구역 등 점검 | M28: 6/2 | T28: - 동절기 대비 HVAC설비 시운전 Test 점검 | U28: 10/25 | V28: - 냉각탑 백연 최소화 운전관리(시작) | W28: 11/1 | X28: - Service Air 계통 Drain(동절기 1,3주 격주) | Y28: 12/1
F29: - SDA Lime Slurry Pump Room 전기히트 철거 | G29: 3/10 | J29: - 주보일러 가동전 점검 | K29: 5/27? | L29: '- 고압가스(CO2) 방출 Test(분기) | V29: - 옥외 펌프류 및 Atomizer Room 동결예방 백열등 점등(외기온도 고려) | W29: 11/16 | X29: - 옥외 펌프류(정지설비) 및 Eye Washer 동결방지 Drain 실시 | Y29: 12/1
F30: - 보조보일러 Fin Fan Cooler 천막 철거, M/H Close | G30: 3/10 | J30: - Inter-lock Test(w.전기제어팀, PSM관련) | K30: OH기간 | V30: - 건물 SUH 가동(11월말~12월초 기온 고려) | W30: 11/16 | X30: '- 고압가스(CO2) 방출 Test(분기)
F31: '- 고압가스(CO2) 방출 Test(분기)
B33: * "설비점검 및 회전기기 교체운전(일일,주간,월간,분기)"은별도 | D33: * "설비점검 및 회전기기 교체운전(일일,주간,월간,분기)"은별도 | F33: * "설비점검 및 회전기기 교체운전(일일,주간,월간,분기)"은별도 | H33: * "설비점검 및 회전기기 교체운전(일일,주간,월간,분기)"은별도 | J33: * "설비점검 및 회전기기 교체운전(일일,주간,월간,분기)"은별도 | L33: * "설비점검 및 회전기기 교체운전(일일,주간,월간,분기)"은별도 | N33: * "설비점검 및 회전기기 교체운전(일일,주간,월간,분기)"은별도 | P33: * "설비점검 및 회전기기 교체운전(일일,주간,월간,분기)"은별도 | R33: * "설비점검 및 회전기기 교체운전(일일,주간,월간,분기)"은별도 | T33: * "설비점검 및 회전기기 교체운전(일일,주간,월간,분기)"은별도 | V33: * "설비점검 및 회전기기 교체운전(일일,주간,월간,분기)"은별도 | X33: * "설비점검 및 회전기기 교체운전(일일,주간,월간,분기)"은별도
A35: 안전, 인허가 | B35: - 정기 안전보건교육(안전팀자료, 파트별) | C35: 25일전후(목) | D35: - 정기 안전보건교육(안전팀자료, 파트별) | F35: - 정기 안전보건교육(안전팀자료, 파트별) | H35: - 정기 안전보건교육(안전팀자료, 파트별) | J35: - 정기 안전보건교육(안전팀자료, 파트별) | L35: - 정기 안전보건교육(안전팀자료, 파트별) | N35: - 정기 안전보건교육(안전팀자료, 파트별) | P35: - 정기 안전보건교육(안전팀자료, 파트별) | R35: - 정기 안전보건교육(안전팀자료, 파트별) | T35: - 정기 안전보건교육(안전팀자료, 파트별) | V35: - 정기 안전보건교육(안전팀자료, 파트별) | X35: - 정기 안전보건교육(안전팀자료, 파트별)
B36: - '전년도 안전작업허가서 회수,확인,보관 | D36: - '전년도 안전작업허가서 회수,확인,보관 | E36: (1월지연시) | F36: - Tag 발행 및 회수 관리 현황 점검(분기별) | G36: 4주차 | L36: - Tag 발행 및 회수 관리 현황 점검(분기별) | M36: 4주차 | R36: - Tag 발행 및 회수 관리 현황 점검(분기별) | S36: 4주차 | X36: - Tag 발행 및 회수 관리 현황 점검(분기별) | Y36: 4주차
A39: 기타 | B39: - 유연탄 항차 탄종 연소성(사용 적정성) 분석 [조달부서 요청시]

Sheet 설비 정기점검&교체운전
B2: 설비운영팀 설비점검 및 회전기기 교체운전 List 및 주기
J3: 설비운영팀('26.01.20)
B5: ▣ 주설비 운전분야 설비점검
B6: 점검 주기 | D6: Shift | F6: 점검사항 | G6: 담당 | H6: 결재 | I6: 공유 | J6: 비고
D7: D/S | E7: N/S | G7: Position
B8: 일간 | C8: 매일 | D8: ● | E8: ● | F8: 교대근무 업무일지 | G8: CCR/Local | H8: 파트장 | I8: 앱 공유 | J8: 모바일 일지
C9: 매일 | E9: ● | F9: 야간 순찰 점검 일지 | G9: Local | H9: 팀장 | I9: -
C10: 매일 | E10: ● | F10: 동파방지 점검일지(동결, 동파 취약개소) | G10: Local | H10: 팀장 | I10: - | J10: 최저온도(-3도 이하시)
C11: 매일 | E11: ● | F11: FBHE, Seal Pot Blower V-Belt 상태 점검 | G11: Local | H11: - | I11: - | J11: 현장 V-Belt 교체 현황판 관리
C12: 매일 | E12: ● | F12: 회전기기 Suction Filter 상태 점검 | G12: Local | H12: - | I12: -
C13: 매일 | E13: ● | F13: 6.9kV Pump Suction Strainer DP 점검 | G13: CCR/Local | H13: - | I13: - | J13: BFP, MCWP, ACWP, COP, CCWP
C14: 매일 | E14: ● | F14: Day Silo(Bio, Coal) CO 수치 점검 (CO₂ Tank Level 점검) | G14: Local | H14: - | I14: -
C15: 매일 | E15: ● | F15: 대기오염방지시설 DP 점검 및 운전정보시스템 입력 | G15: Local | H15: - | I15: -
C16: 매일 | E16: ● | F16: Bio Hopper Bin 내부 점검 및 청소 | G16: Local | H16: - | I16: -
C17: 매일 | D17: ● | E17: ● | F17: 주보일러 연소실 Bed Ash 배출(4회/일) | G17: Local | H17: - | I17: - | J17: 배출량 2톤/회.호기, 필요시 추가
C18: 매일 | E18: ● | F18: Boiler Air Comp. #B&C 무부하 30분 운전 | G18: Local | H18: - | I18: -
C19: 매일(주중) | F19: 고압가스(CO2) 일일 안전점검 | G19: 안전팀/최부식 | H19: (안전팀장) | I19: - | J19: (관리원: 안전팀 소방담당자)
B20: 주간 | C20: 매주(일) | D20: ● | F20: LNG System 점검 | G20: Local | H20: 팀장 | I20: TM회의 | J20: 검침기 이용
C21: 매주(일) | E21: ● | F21: 보일러 Soot Blower 점검 | G21: Local | H21: 파트장 | I21: TM회의
C22: 매주(토) | D22: ● | F22: Aux BLR Air-Comp 기동 Test 회전기기 Hand Turning | G22: Local | H22: - | I22: -
C23: 매주(화,금) | E23: ● | F23: Bed Ash Vibrating Screen 청소 | G23: Local | H23: - | I23: - | J23: 막힘 상태에 따라 수시 실시
C24: 매주(목) | D24: ● | F24: Lime Slurry Density Meter Flushing, Lime Slurry Feed Tank 상부 Screen 이물질청소 | G24: Local | H24: - | I24: -
C25: 매주(월) | E25: ● | F25: Bed Ash Bucket Elevator 하부 점검(청소) | G25: Local | H25: - | I25: - | J25: BE601: 설비상태에 따라 매일
C26: 매주(화) | D26: ● | F26: Bag Filter Off-Line Mode 진행 | G26: CCR | H26: - | I26: -
C27: 매주(월) | E27: ● | F27: Fly Ash Sampling (N조=> 화요일 02시경) | G27: Local | H27: - | I27: - | J27: 화요일 02시 Sampling 실시
C28: 매주(화,금) | D28: ● | F28: SDA Hopper Ash 배출(톤백 2개/회.호기) | G28: Local | H28: - | I28: - | J28: 26년부터 2,8,11월4주차 화,수 (5월 OH시) Empty배출
C29: 매주(월,목) | D29: ● | F29: SDA Lime Slurry Return Line 점검 | G29: Local | H29: - | I29: 팀 카톡방
C30: 매주(일) | D30: ● | F30: 1,2호기 유기성고형연료 Silo Vent Line Duct 유속 측정 | G30: Local | H30: - | I30: TM회의
C31: 매주(일) | D31: ● | F31: 냉각탑 Damper 작동 Test | G31: CCR/Local | H31: - | I31: - | J31: 동절기는 상황에 따라 시행
B32: 월간 | C32: 매월 4일 | E32: ● | F32: 소화기 점검 | G32: Local 전원 | H32: 팀장 | I32: TM회의
C33: 셋째주(일) | D33: ● | F33: 비상발전기 기동 점검 | G33: Local | H33: 팀장 | I33: TM회의
C34: 셋째주(일) | D34: ● | F34: 주보일러 회전기기 교체 점검 | G34: CCR/Local | H34: 팀장 | I34: TM회의
C35: 짝수월 넷째주(일) | D35: ● | F35: 터빈/발전기 Oil&GSC계통 회전기기 교체운전 점검 | G35: CCR/Local | H35: 팀장 | I35: TM회의
C36: 넷째주(일) | D36: ● | F36: 터빈/발전기 BOP계통, 보조보일러, HVAC및급탕 Sys. 회전기기 교체운전 점검 | G36: CCR/Local | H36: 팀장 | I36: TM회의
C37: 매월 2,4주 (금) | E37: ● | F37: SDA Atomizer 가동 시간(Wheel 교체주기) 점검 | G37: CCR | H37: - | I37: -
C38: 둘째주 (월) | D38: ● | F38: Atomizer Wheel점검 및 Support Cone부위 Cleaning TM발행 | G38: CCR | H38: - | I38: - | J38: 매월(Local운전원: TM작업 전후 사진 촬영 공유 및 기록관리)
C39: 매월 2,4주 (금) | D39: ● | F39: Fly Ash Silo, Lime Silo 상부 Vent Filter/Fan 점검 | G39: Local | H39: - | I39: -
C40: 넷째주(일) | E40: ● | F40: Steam Unit Heater(보일러,터빈 etc) 점검 | G40: Local | H40: - | I40: - | J40: 동절기 Unit Heater 운전시
C41: 매월1,3주 (토) | D41: ● | F41: 동절기 Service Air Line 응축수 Drain | G41: Local | H41: - | I41: - | J41: 동절기(12~3월)
B42: 분기 | C42: 매분기(3.6.9.12m/3w수) | D42: ● | F42: CO2 구역별 방출 Test | G42: Local | H42: 팀장 | I42: - | J42: 안전관리자 입회
...

Sheet 01
B2: 설비운영팀 일일 업무 현황
B3: 46266
B5: 1. 주요 전달 및 지시사항(TM회의 등등 Issue사항) : 팀장(◎대표님, ○부문장님, -팀장, *기타 지시사항)
B6: [TM회의]
B7: - Biio등 혼소연료 혼소운전기준을 기존 일최대량 및 월평균 혼소율 관리에서 일최대 혼소량만 관리하여 운전하고 있음 [참고]
B8: - Bio 일사용량 대비 혼소율 25%이하. 입열량 증가 또는 효율저하, Bio 발열량 감소 등 사유 점검 필요 [이성진+효율]
B9: ○ Fly Ash 발생량 많으므로 환경팀에서는 투입되는 석탄 Ash 성분 등 분석 요망 [환경팀]
B10: ○ TT01지하 Pin Hole 작업 비계 종종 사용하므로 보수작업용 Walk Way설치방안 기계팀에서 검토 요망 [기계팀]
B11: * (파트장) 1호기 유기성고형연료 Blower #B PSV 파손됨. 기계팀 점검 보수 요망 [기계팀]
B12: ○ 금일 SMP 가격 높으므로 혼소량 미충족하더라도 안전하게 연속 최대한 발전운전 요망 [공통]
B14: [설비운영팀]
B15: - 8월 말기준 누적 혼소율 실적 미달. 년말 Bio설비 개선공사 고려하여 년간 목표 혼소율 달성위한 하반기 잔여기간 혼소계획 검토요망 [이성진+효율파트]
B16: - Fly Ash 발생량, Limestone 사용량 등 적정한 것인지 운전실적 점검 요망 [효율파트]
B17: - 설비 안전운전 철저, 운전 특이사항 발생건 및 발생 예상되는 사항 신속 공유 및 보고 요망 [운전파트+효율]
B21: 2. 주요 업무 현황 | J21: 일일발전 운전현황작성
B22: □ 효율파트 업무일지 및 운전파트 주요사항
B23: 구분 | C23: 업무[정+부] | D23: 주요 업무(업무내용, Event, Issue사항 등) | J23: 비 고
B24: 효 율 파 트
C25: 효율업무 총괄
C26: [오현주]
C29: 효율업무1
C30: [이성진]
C33: 효율업무2
C34: [송관석]
C37: 효율업무3
C38: [최수민]
C41: 구매∙행정업무
B44: 운 전 파 트 | C44: Day 근무조 | D44: 1. 0:14,10:20 Generator Main Protection 49G Alarm(Thermal Over Load) 발생 -야간 리셋 요망
C45: 2 | D45: - GEN' Protection Panel 확인결과 Thermal Over Load SP 70% 이상 운전되어 Alarm 발생
C46: =IF(C45=1,"[조용환+]",IF(C45=2,"[한만석+]",IF(C45=3,"[남정현+]",IF(C45=4,"[김광표+]","???")))) -> [한만석+] | D46: - 계통 무효전력 상승으로 발전기 전류 상승되면서 Thermal 상승 추정
D47: - 평일 오전 부하 상승 시 GEN' 역률 0.96이하로 떨어질 때와 00시에 Excel Sheet 기입 요망 - TGO
D48: 2. 본관동 지하 급탕 탱크 대류 펌프 샤프트측 고착 해소 후 정상 기동 확인 - TM 작업
D49: 3. 유기성 고형연료 1-B Blower 전류치 16A, 소음 및 진동 발생확인, 후단 Safety Line 이탈 확인 | J49: TM 발행
D50: - 축분쪽 신설 Blower 이설 후 1-B측에 설치하여 기동 예정(명일까지 이설 작업계속) / 1-B는 반출 예정
D51: - #1 BLR 유기성 고형연료 Blower #B 후단 PSV Line 이탈됨 | J51: TM 발행
D52: 4. #2 Bed Ash Air Lock Feeder Inlet Dome Valve Actuator 고정 볼트 4EA 유실 - 작업 완료 | J52: TM 작업 완료
D53: 5. #2 BLR Bed Ash Surge Bin Aeration Tubing Line Pinhole | J53: TM 발행
D54: 6. #2 BLR Soot Blower #23 Poppet Valve 위치 조정 하여 점검 완료 - 야간 Soot Blower 진행시 확인 요망
D55: 7. #2 BLR Back Pass Inlet Press #C 점검 실시-계측기 Manifold Vent Line이 Open되지 않음. -> 오버홀 작업 예정.
D56: * Bed Ash Scrap Box 명일 폐기물로 배출예정 - 명일 8894 차량으로 우선 처리 요망
...

Sheet 02
B2: 설비운영팀 일일 업무 현황
B3: ='01'!B3+1 -> 46267
B5: 1. 주요 전달 및 지시사항(TM회의 등등 Issue사항) : 팀장(◎대표님, ○부문장님, -팀장, *기타 지시사항)
B6: [TM회의]
B7: - 금일 및 명일(수,목) Fly Ash 반출 Arm Roll 차량 2대/일 반출 예정. 금일도 유기성고형연료는 운영지원팀에서 배차량 축소 예상/ 어제 발생한 발전기 Thermal Alarm은 아직 Reset은 안된상태 [참고]
B8: ○ 내일부터 운전파트 교대직 BO1 또는 BO2 휴가자 발생시 주간시간 대근자는 현재 효율파트 일근지 최수민 주임 대근자 투입 요망 [운전파트+공통]
B9: ○ Fly Ash 발생량 적정한지 효율파트에서도 검토 요망 [이성진+송관석]
B10: * (안전팀) 대표님 순잘 지적사항 등 각팀 안전 및 개선조치 요청사항 조치결과 Feedback 요망 [공통]
B11: * (안전팀) TT01 지하1층 메쉬망 추가설치, 보조보일러 1층 자재 정리 및 Fence 설치 등 조치 요망 [참고]
B12: ○ 미이용산림 및 축분 연료 혼소 관련 통합환경영향평가 어제 승인됨. 환경팀 많은 수고하였음. 탈석탄 관련 업무도 환경팀에서 공무역할 수행하며, TFT에서도 관련인원 4명만 주업무 수행하는 상황 [참고]
B13: - 입고탄 26-1항차 ADB기준 회분함량 6.7% 너무 낮은거 같으므로 재분석 요망 [환경팀]
B14: * (기계팀) 금일 1호기 유기성고형연료 Blower #B는 신설한 축분이송 블로워로 교체 설치 예정 [참고]
B15: ○ 구미발전소 GIS문제로 Shutdown 됨. 원인 확인 요망 [전기제어팀]
B16: ○ 환경팀 충원 어려울것 같음. 전기제어팀 김지우대리 결원시 최수민 주임 투입 또는 최수민주임 운전파트 및 운전파트원 기계팀 이동 건은 미정상태로 좀더 검토 필요 예상 [참고]
... B21: - 여유있을때 터빈동 1층 바닥등 오염 심한 곳은 청소요망. Fly Ash Wet Unloading 작업시 안전작업 지원 요망 [운전파트]
B26: 2. 주요 업무 현황 | J26: 일일발전 운전현황작성
B27: □ 효율파트 업무일지 및 운전파트 주요사항
B28: 구분 | C28: 업무[정+부] | D28: 주요 업무(업무내용, Event, Issue사항 등) | J28: 비 고
B29: 효 율 파 트
C30: 효율업무 총괄
C31: [오현주]
C34: 효율업무1
C35: [이성진]
C38: 효율업무2
C39: [송관석]
C42: 효율업무3
C43: [최수민]
C46: 구매∙행정업무
B49: 운 전 파 트 | C49: Day 근무조 | D49: 1. #1 BLR 유기성 고형연료 Rotary #B 상부 Slide Gate 동작 불량 | J49: TM 발행
C50: 2 | D50: 2. #1,2 BLR 유기성 고형연료 Blower Suction Filter Cleaning 요청 | J50: TM 발행
C51: =IF(C50=1,"[조용환+]",IF(C50=2,"[한만석+]",IF(C50=3,"[남정현+]",IF(C50=4,"[김광표+]","???")))) -> [한만석+] | D51: 3. #1 BLR Flue Gas O2 Analyzer #A Calibration 점검 요망 | J51: TM 발행
D52: 4. Fly Ash Wet Unloader 배출 - Ammonia 냄새 심하므로 마스크 필히 착용하여 작업 필요 (20ton이하 반출요망)
D53: 5. #1 BLR Bed Ash Air Lock Feeder Discharge Dome Valve Air Leak 발생관련 Dome V/V 교체 후 정상화_TM 작업
D54: 6. #1 BLR 유기성 고형연료 1-B(축분쪽 이설) 부하 기동 실시 후 Line Purge 완료함
D55: 7. #2 BLR Bio Dosing Convayor Vent Filter Fan Bag 교체 완료[T.M작업]
D56: 8. #2 BLR Soot Blower #23 Poppet V/V 점검[T.M작업] - 야간에 동작 상태 점검 필요
D57: 9. #1, 2 BLR SCR Flue Gas NH3 Analyzer 점검 요청 | J57: TM 발행
D58: 10. #2 BLR Bio Reclaimer → Dosing Conveyor Inlet 점검창 상부 Crack | J58: TM 발행
D59: * 야간조 보일러동 전등 이상유무 추가 확인 후 TM 발행 요망 -대표님 지적사항
D60: * 최수민 주임 9월 4,9일 대근 확정 - BO1,BO2동시 휴가 발생시 BO1 우선 대근 신청요망 | J60: 팀장님 지시사항
...

Sheet 03
B2: 설비운영팀 일일 업무 현황
B3: ='02'!B3+1 -> 46268
B5: 1. 주요 전달 및 지시사항(TM회의 등등 Issue사항) : 팀장(◎대표님, ○부문장님, -팀장, *기타 지시사항)
B6: [전일 오후 부문장님 지시사항 : 최수민주임 근무방식 최종확정건]
B7: ○ 최수민 주임은 9/4(금)부터 2층 현장운전원실에서 일근 현장운전원으로 평일 8hr/일 근무(주간시간대 현장원전원 4명으로 운영). BO1 또는 BO2 휴가자 발생시 최수민주임 대근자 투입하고, 초과근무시간은 보상휴무로 정산하여 대체. 주중 및 주말, 휴일 등 D조와 N조 근무 모두 투입토록함.[팀장,최수민+운전파트]
B9: [TM회의]
B10: ○ 설비운영팀에서는 Fly Ash 과다발생 원인 검토 요망[이성진+송관석]. 환경팀에서는 26-1항차 Ash함량 재분석하여 설비운영팀 재공 요망 [환경팀]
B11: * (기계팀) 금주 주말작업 : BC205 Side Skirt 개선작업. 토요일 오전에 연료 15대 입고후 오후부터 일요일까지 본작업 예정. 1호기 Bed Ash V/S 후단 Chute 변경작업 [참고]
B12: ○ 1호기 유기성 Blower Bearing 윤활유 부족이라고하므로 윤활관리 철저. Bio BF202 Rotary Feeder 소음 점검 요망 [기계팀]
B13: ○ 환경팀에서는 보조보일러용 연수설비 철거해도 되는지 검토해서 불필요하면 철거토록 검토 요망 [환경팀]
B14: ○ (주간회의자료 사전 Review) 설비 신설후 시운전 관련 내용은 기계팀에서 기록하고 설비운영팀은 시운전후 정상운전시 문제점 등을 주간회의자료에 기록 요망 [효율파트]
B16: [주간회의]
B17: ◎ 주간회의자료 첫페이지 "주간 판매/매출" 내용 월별 추이, 예상 영업이익 등 전체 Trend 읽을수 있는 자료료 개선 요망 [경영관리실]
B18: ◎ 기계팀 내년 사업계획 수립시 인력 부족시 충원요청할 것. 인원부족으로 휴가사용 어려운 상황 없도록 [기계팀]
... B28: - 설비 오염구역, 미정리 폐자제 등 순찰시 확인햐여 자율적 설비 청결관리 요망. [운전파트+효율]
B32: 2. 주요 업무 현황 | J32: 일일발전 운전현황작성
B33: □ 효율파트 업무일지 및 운전파트 주요사항
B34: 구분 | C34: 업무[정+부] | D34: 주요 업무(업무내용, Event, Issue사항 등) | J34: 비 고
B35: 효 율 파 트
C36: 효율업무 총괄
C37: [오현주]
C40: 효율업무1
C41: [이성진]
C44: 효율업무2
C45: [송관석]
C48: 효율업무3
C49: [최수민]
C52: 구매∙행정업무
B55: 운 전 파 트 | C55: Day 근무조 | D55: 1. BFP #C Discharge Nozzle PI Maniford 상부 Leakage 점검 요청 | J55: TM발행
C56: 3 | D56: 2. HP Process Steam #A-1 Train Letdown Spray Water 인입부 Leakage 점검 요청 | J56: TM발행
C57: =IF(C56=1,"[조용환+]",IF(C56=2,"[한만석+]",IF(C56=3,"[남정현+]",IF(C56=4,"[김광표+]","???")))) -> [남정현+] | D57: 3. #1 Bio Dosing Conveyor Bag Filter 교체 완료
D58: 4. #1 Bed Ash B/E-602,603 Pin-Hole 부위 용접 완료
D59: 5. 유기성 Storage Silo #A 방폭판 교체 완료
D60: 6. #2 Bed Ash Screw Conveyot 303 취부 완료 - 상태양호
D61: 7. Fly Ash Silo Wet Unloader 기동 및 배출 지원
D62: 8. #1, 2 BLR Bio Screw 주변 청소
D63: 9. #2 Bed Ash 반출장 상부 청소
C66: Night 근무조 | D66: 1. #1 BLR Bio Rotary FDR #B 상부 막힘 발생 : 막힘해소 및 주변 청소 실시
C67: 4 | D67: 2. #2 BLR Bed Ash Bucket Elevator-602 하부 Casing 조립 완료
C68: =IF(C67=1,"[조용환+]",IF(C67=2,"[한만석+]",IF(C67=3,"[남정현+]",IF(C67=4,"[김광표+]","???")))) -> [김광표+] | D68: 3. #2 BLR Bed Ash Arm Roll Box 교체 실시
...

Sheet 04
B2: 설비운영팀 일일 업무 현황
B3: ='03'!B3+1 -> 46269
B5: 1. 주요 전달 및 지시사항(TM회의 등등 Issue사항) : 팀장(◎대표님, ○부문장님, -팀장, *기타 지시사항)
B6: [TM회의]
B7: ○ Fly Ash 과다발생 원인 신속히 검토하여 차주 화요일 대표님께 보고 요망. 유연탄, 유기성, Bio 등 Ash 함량 고려시 비정상적으로 과다배출됨. 운전 잘못되고 있을수도 있으므로 운전상태 적절한지도 검토 필요 [이성진,송관석+운전파트]
B8: ○ 4주차 화요일 TM회의에는 자이E운영 기계팀장 및 전기제어팀장도 회의 참석 요망 [자이E]
B9: * (기계팀) 금주 주말작업 계획 : BC205 Side Skirt 개선, BC206 감지기, 1호기 Bed Ash 잡출물 배출 Chute 위치 이동(암롤박스 중앙부로) [참고]
B10: ○ 주말 작업시 BF202,203 Rotary Feeder 소음 점검 요망 [기계팀]
B12: [설비운영팀]
B13: - 주말에 주보일러 1,2호기 분담하여 오염구역 청소 철저. 주보일러 중앙계단 등 저층부 주요통로 거미줄 제거 요망. 여유 있으면 보조보일러 1층 바닥 건식으로하도 청소 요망(오염 심함) [운전파트]
B14: - Fly Ash 발생량 과다건 관련 운전상태 특이사항 또는 과다발생 원인 발생시 효출파트 신속 정보 공유 요망. 월요일까지 검토하여 화요일 보고 예정[운전파트+효율]
B15: - 주말 설비운전 특이사항 발생시 신속 상황 공유 요망. 주말 정비부서 개선 및 정비작업 협조 운전. 설비 안전운전 및 안전관리 철저 [운전파트]
B19: 2. 주요 업무 현황 | J19: 일일발전 운전현황작성
B20: □ 효율파트 업무일지 및 운전파트 주요사항
B21: 구분 | C21: 업무[정+부] | D21: 주요 업무(업무내용, Event, Issue사항 등) | J21: 비 고
B22: 효 율 파 트
C23: 효율업무 총괄
C24: [오현주]
C27: 효율업무1
C28: [이성진]
C31: 효율업무2
C32: [송관석]
C35: 일근현장운전원
C36: [최수민]
C39: 구매∙행정업무
B42: 운 전 파 트 | C42: Day 근무조 | D42: 1. #1 BLR FBHE Blower #A V-Belt 교체요청 | J42: TM발행-작업완료
C43: 3 | D43: 2. #2 BLR TAH Air Lock Feeder Discharge Dome Valve[ETG22AA104] 작동 불량 점검 요청 | J43: TM발행
C44: =IF(C43=1,"[조용환+]",IF(C43=2,"[한만석+]",IF(C43=3,"[남정현+]",IF(C43=4,"[김광표+]","???")))) -> [남정현+] | D44: 3. #2 BLR 유기성 고형연료 Blower #B 토출 Line 점검요망 | J44: TM발행
D45: 4. #1 Bag Filter 'A-5' Inlet Dome Valve 교체작업 완료
D46: 5. 10:39 #1 FBHE Blower #A → #C 교체운전실시 - #A V-Belt 교체완료 및 Stand By
D47: 6. #1,2 SDA Hopper Ash 배출 - 톤백 2EA
D48: 7. #1,2 BLR 유기성 고형연료 Blower Sucting Filter 교체
D50: - 9/7 #1,2 Bed Ash Room 중장비 지원 청소 예정
D51: - 주말 Bed Ash 차량 배차 없음, 차주 월요일 부터 4대 입고예정
D52: - Bio 상탄설비 Belt Conveyor 205 작업으로 상탄불가 (토 08:00 ~ 일 16:00)
D53: - Fly Ash Sampling은 9/6 N/S (9/7, 02:00) 실시 요함 - 9/7 오전에 분석예정 (효율팀 요청)
C54: Night 근무조 | D54: 1. #2 BLR Bio Reclaimer 구리스 투입 라인 점검 요청 : 투입 라인 막힘 의심 | J54: TM발행
C55: 4 | D55: 2. #1 Bed Ash Air Lock Feeder 후단 막힘 : Bed Ash 이송불가 | J55: TM발행
C56: =IF(C55=1,"[조용환+]",IF(C55=2,"[한만석+]",IF(C55=3,"[남정현+]",IF(C55=4,"[김광표+]","???")))) -> [김광표+] | D56: 3. #2 BLR SDA Atomizer Lube Oil 충유 실시
D57: 4. Boiler Air Compressor #B, C 무부하 운전 30분 실시
...

Sheet 05
B2: 설비운영팀 일일 업무 현황
B3: ='04'!B3+1 -> 46270
B5: 1. 주요 전달 및 지시사항(TM회의 등등 Issue사항) : 팀장(◎대표님, ○부문장님, -팀장, *기타 지시사항)
B15: 2. 주요 업무 현황 | J15: 일일발전 운전현황작성
B16: □ 효율파트 업무일지 및 운전파트 주요사항
B17: 구분 | C17: 업무[정+부] | D17: 주요 업무(업무내용, Event, Issue사항 등) | J17: 비 고
B18: 효 율 파 트
C19: 효율업무 총괄
C20: [오현주]
C23: 효율업무1
C24: [이성진]
C27: 효율업무2
C28: [송관석]
C31: 일근현장운전원
C32: [최수민]
C35: 구매∙행정업무
B38: 운 전 파 트 | C38: Day 근무조 | D38: 1. #2 BLR Fly Ash Air Lock Feeder 'A-3' Discharge Dome Valve Seat 손상 점검 요청 | J38: tm 발행
C39: 1 | D39: 2. #2 BLR Fly Ash Air Lock Feeder 'A-1' Discharge Dome Valve Seat 손상 점검 요청 | J39: tm 발행
C40: =IF(C39=1,"[조용환+]",IF(C39=2,"[한만석+]",IF(C39=3,"[남정현+]",IF(C39=4,"[김광표+]","???")))) -> [조용환+] | D40: 3. [TM작업]#1 Bed Ash Air Lock Feeder Disch' Line 관통작업 완료
D41: 4. 보조보일러 Compressor 무부하 기동 테스트 및 BFP Hand Turning 실시
D42: 5. #1 Bed Ash 잡철물 배출 Chute 위치조정 작업 완료
D43: 6. 보조보일러 1F 청소 실시& 1호기 7-5F 청소 실시
C45: Night 근무조 | D45: 1. #2 BLR Bio Feeding System 정지
C46: 2 | D46: - Screw Feeder측 글라스울 설치, Manual Slide Gate Close, Hopper Bin 청소 실시
C47: =IF(C46=1,"[조용환+]",IF(C46=2,"[한만석+]",IF(C46=3,"[남정현+]",IF(C46=4,"[김광표+]","???")))) -> [한만석+] | D47: 2. BFP #A 주변, #1 BLR 4.5~2층및 거미줄 제거 청소 실시
D48: 3. BLR Compressor #B 무부하 운전 30분 실시
B52: ※ 1) 연료관리 : 자이E 업무일지 참고. 2) 운전파트 : 주요 Event, 파트별 주요 전달 및 공유사항 등 기록하고, 상세사항 업무일지에 기록. 3) 필요시 행추가 후 작성
B54: 3. 기타사항 : 근태사항(사용일자 Sheet에 휴가자 및 대근자 명기), 협의 또는 요청사항 등등(작성자 또는 파트 명기)
B55: 1. 연차휴가 : 고석훈 대리(대근자 김현상 대리)

Sheet 06
B2: 설비운영팀 일일 업무 현황
B3: ='05'!B3+1 -> 46271
B5: 1. 주요 전달 및 지시사항(TM회의 등등 Issue사항) : 팀장(◎대표님, ○부문장님, -팀장, *기타 지시사항)
B15: 2. 주요 업무 현황 | J15: 일일발전 운전현황작성
B16: □ 효율파트 업무일지 및 운전파트 주요사항
B17: 구분 | C17: 업무[정+부] | D17: 주요 업무(업무내용, Event, Issue사항 등) | J17: 비 고
B18: 효 율 파 트
C19: 효율업무 총괄
C20: [오현주]
C23: 효율업무1
C24: [이성진]
C27: 효율업무2
C28: [송관석]
C31: 일근현장운전원
C32: [최수민]
C35: 구매∙행정업무
B38: 운 전 파 트 | C38: Day 근무조 | D38: 1. 1,2 Fly Ash Handling System Fast Mode 전환_ 발생량 Raw data test | J38: 팀장님 지시사항
C39: 1 | D39: 2. 2호기 보일러 7-5F 청소 실시
C40: =IF(C39=1,"[조용환+]",IF(C39=2,"[한만석+]",IF(C39=3,"[남정현+]",IF(C39=4,"[김광표+]","???")))) -> [조용환+] | D40: 3. #1,2 BLR FBHE Blower Suction Filter 교체요청 | J40: tm 발행
D41: 4. NG System 주간점검 실시
C45: Night 근무조 | D45: 1. 2호기 4.5-2F 청소및 거미줄 제거, 터빈동 1층 거미줄 제거 실시
C46: 2 | D46: 2. #1,2 BLR Fly Ash Sampling 실시
C47: =IF(C46=1,"[조용환+]",IF(C46=2,"[한만석+]",IF(C46=3,"[남정현+]",IF(C46=4,"[김광표+]","???")))) -> [한만석+] | D47: 3. 1,2호기 Flue Gas CO Analyzer 점검 요청 | J47: TM 발행
D48: 4. [HCB30AT004] #2 BLR Soot Blower #5 Gland 측 Steam Leak | J48: TM 발행
D49: 5. #1,2 BLR BLR Soot Blower 주간점검 실시
B52: ※ 1) 연료관리 : 자이E 업무일지 참고. 2) 운전파트 : 주요 Event, 파트별 주요 전달 및 공유사항 등 기록하고, 상세사항 업무일지에 기록. 3) 필요시 행추가 후 작성
B54: 3. 기타사항 : 근태사항(사용일자 Sheet에 휴가자 및 대근자 명기), 협의 또는 요청사항 등등(작성자 또는 파트 명기)

Sheet 07
B2: 설비운영팀 일일 업무 현황
B3: ='06'!B3+1 -> 46272
B5: 1. 주요 전달 및 지시사항(TM회의 등등 Issue사항) : 팀장(◎대표님, ○부문장님, -팀장, *기타 지시사항)
B15: 2. 주요 업무 현황 | J15: 일일발전 운전현황작성
B16: □ 효율파트 업무일지 및 운전파트 주요사항
B17: 구분 | C17: 업무[정+부] | D17: 주요 업무(업무내용, Event, Issue사항 등) | J17: 비 고
B18: 효 율 파 트
C19: 효율업무 총괄
C20: [오현주]
C23: 효율업무1
C24: [이성진]
C27: 효율업무2
C28: [송관석]
C31: 일근현장운전원
C32: [최수민]
C35: 구매∙행정업무
B38: 운 전 파 트 | C38: Day 근무조 | D38: 1. #2 BLR Limestone Rotary Feeder #B Gland Leak : Gland Tighting 했지만 계속 Leak 중 | J38: TM발행 : 작업완료
C39: 4 | D39: 2. #1 BLR Bio Reclaimer Grease 자동 주입기 Air Line 호스 교체 요청 | J39: TM발행
C40: =IF(C39=1,"[조용환+]",IF(C39=2,"[한만석+]",IF(C39=3,"[남정현+]",IF(C39=4,"[김광표+]","???")))) -> [김광표+] | D40: 3. #2 BLR Eco Air Lock Feeder #B Discharge Dome Valve Close 불량 | J40: TM발행
D41: 4. #2 BLR Eco Air Lock Feeder #A Equlaizing Valve 상층부 Ash Leak | J41: TM발행
D42: 5. #1 BLR 유기성 고형연료 Rotary Feeder #B 기동 불량 : Motor 기동되나 Rotary 동작안됨 | J42: TM발행
D43: 6. Fly Ash Wet Unloader 배출 지원 실시 : Arm Roll Box 차량 2대
D44: 7. #1 BLR Bed Ash Magnetic Separator 점검 결과 특이 사항 없어 Relay 교체 실시 : 추이 관찰 예정
D45: 8. #1 BLR Main Steam Bypass MOV, DSH-1 Spray MOV 점검 실시 : 특이사항 없으며 현재 동작 테스트 불가 | J45: 추후 정지 시 점검
D46: 9. #1 BLR Bed Ash Bucket EL-603 Outlet Chute (5F) Pinhole 부위 덧댐 용접 작업 완료
D47: 10. #1 BLR FBHE Blower Suction Filter 교체 완료
D48: 11. #1 BLR Soot Blower #14 Poppet Valve 스프링 장력 조절 실시 : 기동 테스트 양호
D49: 12. #2 BLR Limestone Rotary Feeder #B Gland Leak 되어 Packing 교체 완료
D50: 13. #2 BLR Soot Blower #5 Gland Packing 추가 작업 실시 : 야간 조 확인요망
D51: 14. #2 BLR Bio Reclaimer 구리스 투입라인 막힘 점검 결과 투입라인 문제 없음 : 구리스 투입 시간 8분으로 조정 | J51: 추이 관찰 요망
D52: 15. #2 BLR TAH Air Lock Feeder #B Discharge Dome Valve 내부 Ash 해소 후 Open/Close 상태 양호
D53: 16. #2 BLR 유기성 고형연료 Blower #B 토출 Line 점검 실시 : Ejector 내부 이물질 제거 후 Air Purge 정상화
D54: 17. HP Process STM Spray Water Leak건 명일 비계 설치하여 보온재 해제후 확인 예정
C56: Night 근무조 | D56: 1. #2 Bed Ash Air Lock Feeder Discharge 막힘 및 Pinhole 발생 | J56: TM발행
C57: 3 | D57: 2. #2 BLR Soot Blower #23 Poppet Vavle Close 불량 | J57: TM발행
C58: =IF(C57=1,"[조용환+]",IF(C57=2,"[한만석+]",IF(C57=3,"[남정현+]",IF(C57=4,"[김광표+]","???")))) -> [남정현+] | D58: 3. #1 Arm Roll Box 교체 후 New Arm Roll Box 셔터 옆측으로 배치
D59: 4. 02:00 Fly Ash Sampling 실시
D60: 5. #1,2 Bio Hopper BIn 청소 실시
D61: 6. #1,2 BLR 5~6.5층 벅스테이 및 오염 부위 청소 실시
B63: ※ 1) 연료관리 : 자이E 업무일지 참고. 2) 운전파트 : 주요 Event, 파트별 주요 전달 및 공유사항 등 기록하고, 상세사항 업무일지에 기록. 3) 필요시 행추가 후 작성
...

Sheet 08
B2: 설비운영팀 일일 업무 현황
B3: ='07'!B3+1 -> 46273
B5: 1. 주요 전달 및 지시사항(TM회의 등등 Issue사항) : 팀장(◎대표님, ○부문장님, -팀장, *기타 지시사항)
B6: [TM회의]
B7: - 금일 오전 1,2호기 Bed Ash 반출장 바닥 Ash 장비 이용 정리 예정[설비운영+자이E]
B8: - 1,2호기 Fly Ash 성분분석결과 미연탄소분 높으므로 오늘부터 연소 조정 예정. 긴급 연소 조정에 따른 Fly Ash 성분분석 협조 요망 [환경팀=> 협조 가능]
B9: * (안전팀) 어제 취합한 26년도 정기위헙성평가 취합자료 안전팀에서 Review후 각팀 Feedback 예정 [참고]
B10: * (기계팀) 한전산업개발에서 어제부터 진행하고 있는 고압터빈 감속기 진동 Data Pick-up는 금일 오전에 완료 예정. 분석결과는 추후 제공받을 예정[참고]
B11: * (기계팀) 내일(9/9.(수)) 유기성고형연료 Emergency Screw 감속기 교체, 흔들리는 Support 보완 등 작업 예정. Emergency Feeder 부하테스트은 추후 공지 예정[참고]
B13: [설비운영팀]
B14: - 금일(9/8) 10시부터 1,2호기 연소실 하부 운전온도 약 10도 상향 운전 요망. 그리고 내일 새벽 02시 1,2호기 Fly Ash Sampling하여 오전에 환경팀에 성분분석 의뢰 요망. Sampling시 정확도 있게 시료 잘 채취 요망(초기 취득 Sample은 버릴것) [운전파트+효율]
B15: - Fly Ash 발생량 증가 원인, 감소방안 관련 운전파트 의견 있으면 효율파트 신속 공유 요망. 미연탄소 감소 운전 관련 설비 상태 및 기타 영향(석회석 투입량 급증 등) 관리 철저 [운전파트]
B16: - 각 파트 안전교육, 직무교육 등 교육자료 팀장 메일로 공유 보고 요망 [운전파트]
B22: 2. 주요 업무 현황 | J22: 일일발전 운전현황작성
B23: □ 효율파트 업무일지 및 운전파트 주요사항
B24: 구분 | C24: 업무[정+부] | D24: 주요 업무(업무내용, Event, Issue사항 등) | J24: 비 고
B25: 효 율 파 트
C26: 효율업무 총괄
C27: [오현주]
C30: 효율업무1
C31: [이성진]
C34: 효율업무2
C35: [송관석]
C38: 일근현장운전원
C39: [최수민]
C42: 구매∙행정업무
B45: 운 전 파 트 | C45: Day 근무조 | D45: 1. #1 BLR Soot Blower #1, 2 Gland Packing 측 Steam Leak | J45: TM발행
C46: 4 | D46: 2. #1 BLR 유기성 고형연료 Rotary Feeder #B 내부 이물질 제거 후 기동 실시 : 정상화 완료 | J46: Bag 하부 Cap 제거
C47: =IF(C46=1,"[조용환+]",IF(C46=2,"[한만석+]",IF(C46=3,"[남정현+]",IF(C46=4,"[김광표+]","???")))) -> [김광표+] | D47: 3. #1, 2 Bed Ash Room 톤백 정리 및 청소 실시 : 미니 굴삭기 지원
D48: 4. #1, 2 BLR SDA Hopper Ash 배출 및 Vent Fan Bag 청소 실시 : 톤백 각각 2EA | J48: Ash 상태 양호
D49: 5. #1 BLR Bio Reclaimer 구리스 주입기 Air Hose 손상 부 컷팅 후 재연결 실시
D50: - 재손상 발생하여 Air Leak 및 구리스 투입 불량하여 명일 Hose 교체 예정
D51: 6. #2 BLR SA Fan Lower Damper Air Regulator Leak부 페럴 교체 후 정상화 실시
D52: 7. #2 BLR 유기성 고형연료 #2-B Train 투입량 점검 : Blower 유량 부족으로 Rotary->Ejector 흡입압 부족 추정 | J52: 정비전까지 현상태 유지
D53: 8. #2 BLR Bed Ash Air Lock Feeder Discharge Line 내부 이물질 제거 후 정상화 실시
D54: 9. #2 BLR T.A.H 하부 Air Lock Feeder 702 Discharge Dome Valve 내부 이물질 제거 후 정상화 실시
D55: 10. #2 BLR Soot Blower #23 Poppet Valve 교체 실시 : 명일 압력셋팅 예정 (금일 기동금지)
D56: 11. #2 BLR Bed Ash Silo Ash 3대 반출 완료
D57: 12. LP Let Down Train #1 PCV Supply Air 압력 조정 완료
D58: 13. TBN Lube Oil Tank 상부 청소 실시
...

Sheet 09
B2: 설비운영팀 일일 업무 현황
B3: ='08'!B3+1 -> 46274
B5: 1. 주요 전달 및 지시사항(TM회의 등등 Issue사항) : 팀장(◎대표님, ○부문장님, -팀장, *기타 지시사항)
B6: [TM회의]
B7: - 1호기 SDA Atomizer #C 정지상태. 정비부서 신속 정상화 요망. 석회석 투입량 과다시 Atomizer 유량 증대 운전 할수도 있음[참고]
B8: - BC102 #B Tail Part Duct Collection Duct 막힘 해소작업 신속 조치 요망. 외주작업 시행시 점검창 및 안전발판, Duct 단관 길이 분할 등 개선방안 검토 요망[기계팀]
B9: - TT 5개소 및 주보일러 Bag Filter 상부 2개소 조류 침입방지 개선 미적용 상태. 추가적용 방안 검토 요망 [기계팀+자이E]
B10: * (안전팀) 금일 크레인 등 외주공사 중장비 작업 있음 [참고]
B11: * (전기제어팀) 금일 유기성고형연료 사이로 #B Emergency Screw #A 감속기 교체작업후 오후에 무부하 및 부하운전 Test 예정[전기,기계팀+설비운영팀]
B13: [설비운영팀]
B14: - 2027년 예산 및 설비운영계획 작성 및 회신준비[송관석 대리]
B15: - 주보일러 Fly Ash 과다발생 원인, 주말과 주중 발생량 편차 과다 원인, 미연탄소분 감소 운전 등 검토. 운전파트에서도 검토의견 지원 요망 [이성진+송관석,운전파트]
B16: - 주보일러 Fly Ash 미연탄소분 감소 위해 특이사항 없으면 1,2호기 연소실 하부 온도 825~830도 구간에서 안전적인 운전 요망. 내일 새벽에도 Fly Ash Sampling하여 환경팀에 분석의뢰 요망 [운전파트+효율]
B17: - 효율파트 업무일지 기록 요망. TM회의에 삽입내용 표기하고 운전파트에서 TM회의 작성시 확인하여 해당사항 추가[효율파트+운전]
B22: 2. 주요 업무 현황 | J22: 일일발전 운전현황작성
B23: □ 효율파트 업무일지 및 운전파트 주요사항
B24: 구분 | C24: 업무[정+부] | D24: 주요 업무(업무내용, Event, Issue사항 등) | J24: 비 고
B25: 효 율 파 트
C26: 효율업무 총괄
C27: [오현주]
C30: 효율업무1
C31: [이성진]
D33: 1. 8월 발전운영실적 보고
C34: 효율업무2 | D34: 2. 8월 연료사용일지 및 우드칩 사용실적 송부 (환경팀)
C35: [송관석] | D35: 3. 8월 전기 및 증기 실적 송부 (환경팀)
D36: 4. 신입사원(전민정 주임) 성과 목표 송부 (경영관리실)
C38: 일근현장운전원
C39: [최수민]
C42: 구매∙행정업무
B45: 운 전 파 트 | C45: Day 근무조 | D45: 1. #2 BLR Eco Air Lock Feeder #A Discharge Dome Valve Close 불량 | J45: TM 발행
C46: 2 | D46: 2. #2 BLR TAH Air Lock Feeder #A Discharge Dome Valve 작동 불량 점검 요청 | J46: TM 발행
C47: =IF(C46=1,"[조용환+]",IF(C46=2,"[한만석+]",IF(C46=3,"[남정현+]",IF(C46=4,"[김광표+]","???")))) -> [한만석+] | D47: 3. #2 BLR Fly Ash Air Lock Feeder 'A-5' Discharge Dome Valve Tubing Line Pinhole | J47: TM 발행
D48: 4. 유기성 고형연료 Day Silo Vent Fan Bag Filter 점검 요청 | J48: TM 발행
D49: 5. #1 BLR S/B #1,2 Gland Tightging 실시- Tighting 후 기동 시 Steam Leak 심하여 Packing 교체 예정
D50: 6. 유기성 고형연료 Storage Silo #B 축분 Line 무부하 및 부하 Test 실시 - 내용 공유
D51: - 유기성 Day Silo 상탄라인 Support 추가 설치 - 이송시 상태 확인 필요함
D52: 7. #2 BLR Bio Dosing Convayor 상부 점검창 점검 완료
D53: 8. #2 BLR Soot Blower #23 Poppet Valve 압력 설정 실시 - 야간에 Soot 진행시 확인 요청
D54: 9. AHU-203 실외기 Comp' Oil 50%까지 충유
D55: * 10일 02시 Fly Ash Sampling 요망 - 채취시 1~3회 외부로 버리고 그 다음 회부터 채취 요망
...

Sheet 10
B2: 설비운영팀 일일 업무 현황
B3: ='09'!B3+1 -> 46275
B5: 1. 주요 전달 및 지시사항(TM회의 등등 Issue사항) : 팀장(◎대표님, ○부문장님, -팀장, *기타 지시사항)
B6: [TM회의]
B7: - 전일 Fly Ash 발생량도 높은것 같음. 금일새벽 채취한 Fly Ash Sample은 환경팀에서 가능한 신속히 미연탄분 분석 요망[참고]
B8: - 전일에 이어서 금일에도 유기성 고형연료 부하 테스트 운전. 기계팀 Blower 선조치 등 각팀 협조 요망 [참고]
B10: [주간회의]
B11: ◎ 지표현황에 SMP와 증기판매량 당월 실적은 예상치로 트랜드 작성요망. 혼소율 현황에는 누계자료 추가 요망 [경영관리실]
B12: - '27년도 운전 Data 작성위해 혼소연료, 혼소율 등 전략적 사항 결정 필요 => (경영관리실) 회의후 방향 협의
B13: * (환경팀) 바이오 혼소율 29% 상향하는 환경영향평가 변경협의 9차 준비중 [참고]
B14: * (환경팀) 업무혁신 협의회 참석시 10월말경 AX 경진대회 예정 언급됨 [참고]
B15: ◎ 유기성고형연료 축분라인 시운전시 설계용량 대비 실제 투입량도 비교 요망 [기계팀]
B16: ◎ Coal Crusher Building 1층 바닥, 냉각탑 앞뒤 안쪽 Walk way 등 구배불량으로 배수 안되는 곳 개선 요망. Crusher동 철근 배근절단 구조상 문제로 개선 안되면 안전상 문제 되는지 구조진단 받든지 콘크리트를 추가 타설하던지 개선 요망 [운영지원+안전팀]
B17: * (사업개발팀) RPS제도 개편관련 기후부 의견(안)으로 최초 REC발급일부터 20년 또는 기존 REC계수 50% 적용하여 30년 등 후에 REC 일몰 적용 제도개편 논의되고 있음[참고]
... B27: - 유기성고형연료 축분 공급계통 Screw Feeder 운전 Hz 별 연료 투입량 운전파트에서 트렌드 확인 요망 [운전파트]
B31: 2. 주요 업무 현황 | J31: 일일발전 운전현황작성
B32: □ 효율파트 업무일지 및 운전파트 주요사항
B33: 구분 | C33: 업무[정+부] | D33: 주요 업무(업무내용, Event, Issue사항 등) | J33: 비 고
B34: 효 율 파 트
C35: 효율업무 총괄
C36: [오현주]
C39: 효율업무1
C40: [이성진]
C43: 효율업무2
C44: [송관석]
C47: 일근현장운전원
C48: [최수민]
C51: 구매∙행정업무
B54: 운 전 파 트 | C54: Day 근무조 | D54: 1. #1 BLR Bag Filter B-2 Differential Pressure Transmitter 오지시 | J54: TM 발행
C55: 2 | D55: 2. #1 BLR Bag Filter B-2 Air Pulsing시 Dust 최대 0.6ppm 상승_완료 | J55: TM 발행
C56: =IF(C55=1,"[조용환+]",IF(C55=2,"[한만석+]",IF(C55=3,"[남정현+]",IF(C55=4,"[김광표+]","???")))) -> [한만석+] | D56: 3. 유기성 고형연료 Day Silo 하부 온도계 점검 요망_BM
D57: 4. 유기성 고형연료 Rotary #A Fault 발생[BM발행]
D58: 5. 유기성 고형연료 Storage Silo #B Emer Screw #B Gland 점검 요청 | J58: TM 발행
D59: 6. 유기성 고형연료 Storage Silo #B 하역 라인 막힘 점검 요청 | J59: TM 발행
D60: 7. 유기성 고형연료 Day Silo Weight 점검 요청 | J60: TM 발행
D61: 8. #1 BLR Bag Filter A-3 양호, Bag Filter B-4 상부 덮개 Full Close 작업 완료_TM 작업
D62: - Bag Filter B-2 Bag 1개소 파손 -3개 교체 완료
D63: 9. #1,2 Gland Packing 교체 완료_TM 작업
D64: 10. #1 BLR SDA Outlet PT Line 탈락 건
D65: 11. [103ETG34AA101] #1 BLR Fly Ash B/F Air Lock Feeder 'B-1' Inlet Dome Valve Seat 손상 | J65: TM 발행
...

Sheet 11
B2: 설비운영팀 일일 업무 현황
B3: ='10'!B3+1 -> 46276
B5: 1. 주요 전달 및 지시사항(TM회의 등등 Issue사항) : 팀장(◎대표님, ○부문장님, -팀장, *기타 지시사항)
B6: [TM회의]
B7: - 금일 유기성고형연료계통 TM작업 우선시행 요망 [기계팀]
B8: * (자이 운전) Coal BC102 #B 측 집진 덕트 막힘 해소, Bio BC205 Tail 측 집진 댐퍼 등 정상화 또는 보완 신속 조치 요망 [기계팀]
B9: * (안전팀) 금일부터 자이에너지운영에서 안전설비 개선공사 착수 예정 [참고]
B11: [설비운영팀]
B12: - 전일 Fly Ash 발생량 Eco 및 TAH hopper ash 이송 고려하더라도 많음. 최적운전방안, 감소방안, 원인 등 의견 있으면 효율파트 공유 요망 [공통]
B13: - 금일 오후부터 1,2호기 Fly Ash Sample 2회 채취 요망. 오후 17시경과 새벽 02시경 Soot Blowing 시행전에 Sampling하여 해당호기와 채취날짜 및 시간 기록요망. 차주 월요일 오전에 총 12개(2개호기 x 2회/일 x 3일) Sample 환경팀에 분석 의뢰 요망[운전파트]
B14: - 주말간 안전운전 철저. 주설비 오염구역 청소 및 주요 통로 거미줄 제거 요망. 설비 이상징후 발견시 신속 대응조치 및 상황 보고, 공유 [운전파트]
B19: 2. 주요 업무 현황 | J19: 일일발전 운전현황작성
B20: □ 효율파트 업무일지 및 운전파트 주요사항
B21: 구분 | C21: 업무[정+부] | D21: 주요 업무(업무내용, Event, Issue사항 등) | J21: 비 고
B22: 효 율 파 트
C23: 효율업무 총괄
C24: [오현주]
C27: 효율업무1
C28: [이성진]
C31: 효율업무2
C32: [송관석]
C35: 일근현장운전원
C36: [최수민]
C39: 구매∙행정업무
B42: 운 전 파 트 | C42: Day 근무조 | D42: 1. #1호기 Bed Material Rotary FDR 후단 부 Pinhole - 주변 청소 완료 | J42: TM발행
C43: 3 | D43: 2. #1호기 Bed Material Rotary FDR NDE측 Bed Materia Leak - 주변 청소 완료 | J43: TM발행
C44: =IF(C43=1,"[조용환+]",IF(C43=2,"[한만석+]",IF(C43=3,"[남정현+]",IF(C43=4,"[김광표+]","???")))) -> [남정현+] | D44: 3. Lime Slurry Solution Tank #A Discharge Line 막힘 관통요청 | J44: TM발행
D45: 4. #1,2 Bio Dosing Conveyor Inlet Pinhole 및 Outlet Chute 찢어짐 | J45: TM발행
D46: 5. #1 Fly Ash Bag Filter Air Lock Feeder "A-5" Disch. Dome Valve 교체 작업 완료
D47: 6. #1 유기성 고형연료 Rotary Feeder #A 기동 불가 건 점검 완료 (Bag Filter Cap 제거)
D48: 7. 08:40 유기성 고형연료 Day Silo Vent Fan Bag Pulsing Air 6bar로 상향 조절 실시- 차압 150->80mmh2o
D49: 8. 유기성 Storage Silo #B 하역라인 Booster Air HDR에서 하역XV 전단 연결후 가압하여 막힘 해소 실시.
D50: 9. #1,2 SDA 하부 톤백 2EA배출 실시
D51: 10. 유기성 고형연료 Vent Filter Fan Bag 교체 완료
D52: 11. 17:30 #1,2 Fly Ash Sampling 실시 | J52: 팀장님 Mail 참조
D53: 12. #1 Fly Ash Bag Filter Air Lock Feeder "A-1, A-2" Disch. Dome Valve 교체 작업 중
D54: `
C56: Night 근무조 | D56: 1. #2 BLR Soot Blower #23 Poppet Vavle Close 불량 | J56: TM발행
C57: 4 | D57: 2. #1 BLR Bag Filter 'B-1' Aux. Steam Trap Leak | J57: TM발행
C58: =IF(C57=1,"[조용환+]",IF(C57=2,"[한만석+]",IF(C57=3,"[남정현+]",IF(C57=4,"[김광표+]","???")))) -> [김광표+] | D58: 3. #2 BLR Soot Blower #2 Gland 측 Leak | J58: TM발행
...

Sheet 12
B2: 설비운영팀 일일 업무 현황
B3: ='11'!B3+1 -> 46277
B5: 1. 주요 전달 및 지시사항(TM회의 등등 Issue사항) : 팀장(◎대표님, ○부문장님, -팀장, *기타 지시사항)
B15: 2. 주요 업무 현황 | J15: 일일발전 운전현황작성
B16: □ 효율파트 업무일지 및 운전파트 주요사항
B17: 구분 | C17: 업무[정+부] | D17: 주요 업무(업무내용, Event, Issue사항 등) | J17: 비 고
B18: 효 율 파 트
C19: 효율업무 총괄
C20: [오현주]
C23: 효율업무1
C24: [이성진]
C27: 효율업무2
C28: [송관석]
C31: 일근현장운전원
C32: [최수민]
C35: 구매∙행정업무
B38: 운 전 파 트 | C38: Day 근무조 | D38: 1. #1 BLR Soot Blower #9 Cam 고정 불량으로 기동 불가 | J38: TM발행
C39: 3 | D39: 2. Lime Slurry Solution Tank #A Discharge Line EHT 재부착 요청 | J39: TM발행
C40: =IF(C39=1,"[조용환+]",IF(C39=2,"[한만석+]",IF(C39=3,"[남정현+]",IF(C39=4,"[김광표+]","???")))) -> [남정현+] | D40: 3 #2 BLR Bio Screw Feeder #B 구동 Chain 장력 조정 요청 | J40: TM발행
D41: 4. Lime Slurry #A to Feed Tank #A Line 막힘 해소 완료
D42: 5. 08:00 유기성 고형연료 Day Silo 상부 Vent Filter Fan Pulsing Air 6Bar -> 5Bar 설정 (기계팀 요청)
D43: - 변경 전 차압 30, 11:00 차압 40, 17:00 차압 40
D44: 6. Aux BLR Compressor 무부하 기동 Test 및 BFP Hand Turning 실시
D45: 7. 17:00 #1,2 Fly Ash Sampling 실시
D46: 8. #1 BLR 4.5~7층 및 BFP #B, #C 주변 청소
C48: Night 근무조 | D48: 1. #1 ECO Inlet Feedwater LCV 후단 Drain Double Valve Passing : Valve Tightening 후에도 약 150도 지시 중 | J48: 정지 중 작업사항 추가
C49: 4 | D49: 2. #1, 2 BLR Fly Ash Sampling 실시
C50: =IF(C49=1,"[조용환+]",IF(C49=2,"[한만석+]",IF(C49=3,"[남정현+]",IF(C49=4,"[김광표+]","???")))) -> [김광표+] | D50: 3. Boiler Air Compressor #B 무부하 운전 30분 실시
D51: 4. 유기성 고형연료 Day Silo Vent Fan 차압 : 40mmH2O (00:30, 05:00)
D52: 5. #1 BLR 4~2.5F 청소실시
B55: ※ 1) 연료관리 : 자이E 업무일지 참고. 2) 운전파트 : 주요 Event, 파트별 주요 전달 및 공유사항 등 기록하고, 상세사항 업무일지에 기록. 3) 필요시 행추가 후 작성
B57: 3. 기타사항 : 근태사항(사용일자 Sheet에 휴가자 및 대근자 명기), 협의 또는 요청사항 등등(작성자 또는 파트 명기)
B58: 1. 연차휴가 : 김덕용 주임(대근자 박건 주임)
B59: 2. 배우자 출산휴가(9/11~16, 3+3) : 김현상 대리(대근자 고석훈 대리)
B60: 3. 결혼 경조휴가(9/11~16) : 방덕윤 주임(대근자 최수민 주임)

Sheet 13
B2: 설비운영팀 일일 업무 현황
B3: ='12'!B3+1 -> 46278
B5: 1. 주요 전달 및 지시사항(TM회의 등등 Issue사항) : 팀장(◎대표님, ○부문장님, -팀장, *기타 지시사항)
B15: 2. 주요 업무 현황 | J15: 일일발전 운전현황작성
B16: □ 효율파트 업무일지 및 운전파트 주요사항
B17: 구분 | C17: 업무[정+부] | D17: 주요 업무(업무내용, Event, Issue사항 등) | J17: 비 고
B18: 효 율 파 트
C19: 효율업무 총괄
C20: [오현주]
C23: 효율업무1
C24: [이성진]
C27: 효율업무2
C28: [송관석]
C31: 일근현장운전원
C32: [최수민]
C35: 구매∙행정업무
B38: 운 전 파 트 | C38: Day 근무조 | D38: 1. [TM작업]1,2 Dosing Conveyor Outlet Chute 보강 작업 완료
C39: 1 | D39: 2. #2 BLR 5~7F 청소실시
C40: =IF(C39=1,"[조용환+]",IF(C39=2,"[한만석+]",IF(C39=3,"[남정현+]",IF(C39=4,"[김광표+]","???")))) -> [조용환+] | D40: 3. #1,2 BLR Bio Dosing Conveyor Inlet Chute 교체 요청 | J40: TM 발행
D41: 4. #1,2 BLR SDA Atomizer #A,B,C Support Cone 주변 Cleaning 요청 | J41: TM 발행
D42: 5. #2 BLR Bio-SRF Lubrication 운전표시등 점등 상태 점검 요청 | J42: TM 발행
D43: 6. #1 BLR SDA Atomizer #A Inlet Duplex Filter Cleaning 요청 | J43: TM 발행
D44: 7. 1호기 보일러 SDA Inlet Temp Transmitter 오지시 점검요청 | J44: TM 발행
D45: 8. #1 BLR Combustor Bottom Press TX #B 오지시 점검요청 | J45: TM 발행
C46: Night 근무조 | D46: 1. #2 BLR Bed Ash Chain Conveyor Casing 하부 찢어짐으로 Ash Leak | J46: TM 발행
C47: 2 | D47: 2. #2 BLR BLR 청소 및 #5, #6 Heater 주변 청소 실시
C48: =IF(C47=1,"[조용환+]",IF(C47=2,"[한만석+]",IF(C47=3,"[남정현+]",IF(C47=4,"[김광표+]","???")))) -> [한만석+] | D48: 3. #2 BLR Soot Blower #23 Poppet Valve 고착 발생하여 추타 후 정상화
D49: 4. #1 BLR Limestone 사용량 오지시 : 18:00~24:00 6시간 동안 3.2ton 감소함
D50: 5. Fly Ash Silo Level 07:00 ~15:30 8시간 30분 동안 31.5 ton 증가함
D51: 6. 유기성 고형연료 Day Silo Vent Fan 19:50 차압: 40, 05:50 차압: 40
B52: ※ 1) 연료관리 : 자이E 업무일지 참고. 2) 운전파트 : 주요 Event, 파트별 주요 전달 및 공유사항 등 기록하고, 상세사항 업무일지에 기록. 3) 필요시 행추가 후 작성
B54: 3. 기타사항 : 근태사항(사용일자 Sheet에 휴가자 및 대근자 명기), 협의 또는 요청사항 등등(작성자 또는 파트 명기)

Sheet 14
B2: 설비운영팀 일일 업무 현황
B3: ='13'!B3+1 -> 46279
B5: 1. 주요 전달 및 지시사항(TM회의 등등 Issue사항) : 팀장(◎대표님, ○부문장님, -팀장, *기타 지시사항)
B6: [TM회의]
B7: - 석탄은 추석연휴 대비 지난주 토요일에도 입고. 금주 토요일도 입고 예상. 추석연휴 대비 26-3항차 우선사용 위한 소내 Storage Silo에 26-1항차 소내재고 재순환 모으기 운전 등을 미시행 예정(운영지원팀 불필요 의견) => (부문장님) 운영지원팀 재확인 후 Silo 운영관리 요망 [이성진]
B8: - 2027년도 설비운영계획은 시간대별 열수요자료(사업개발팀), 각 혼소연료의 월별 혼소율(운영지원팀) 자료 대기중 => (부문장님) 자료 늦으면 운영부문 (안)으로 Bio 23%, 유기성 6%로 종합 29%로 작성 송부 요망(축분과 미이용산림은 미반영) [송관석+이성진]
B9: - 주보일러 미연탄소분 과다발생 분석건을 전체적인 원인은 추론된 상태로 최종 정리중 => (부문장님) 검토완료되면 대표님께 보고토록 준비 요망[이성진,송관석]
B10: - 3분기 통합비상모의훈련 9/22(화) 예정, 운전원 직무향상 PT발표 마지막주 목요일 일정 확정 필요 => (부문장님) 모의훈련은 9/22(화). 교육 발표는 9/30(수) [운전,효율]
B11: ○ 10월1일 돈분 시운전위해 포천축협에서 돈분 건조중. 금주 수요일까지 미진한 설비 보완하여 목,금에 업체 참석하여 시운전 및 테스트 완료 요망. 10월1일 시운전하고 10월중순경 경기도, 농림축산부 등등 관련기관 합동으로 축분 이용 관련 MOU 체결 예정. 호남권, 영남권, 경기수도권 등 3개권역으로 경기수도권은 GS포천사업장에서 연료 사용하는 것으로 추진 [기계팀+관련부서]
B12: ○ 기계팀에서는 보일러동 5층 창문 추가, 2호기 Bio Reclaimer 개선, Bio Dosing Conveyor Vent Filter 개선, Fly Ash Silo 등 차질없도록 준비 요망. Fly Ash Silo는 금년 11월에 계약해서 동절기에 공장제작하고 내년 OH기간에 설치완료하여 OH후 재기동시 정상화 될수 있도록 준비 요망[기계팀]
B14: [설비운영팀]
B15: - 운전파트 직무교육 발표자료 신속 작성 공유 요망 [운전파트]
B16: - 3분기 통합비상모의훈련 계획 보고 및 공유 요망 [효율파트+1파트]
B17: - 추석연휴 운영계획(근무계획, 원부재료 운영계획 등) 작성 및 보고 위한 각팀 자료 미리 요청 요망 [효율]
B22: 2. 주요 업무 현황 | J22: 일일발전 운전현황작성
B23: □ 효율파트 업무일지 및 운전파트 주요사항
B24: 구분 | C24: 업무[정+부] | D24: 주요 업무(업무내용, Event, Issue사항 등) | J24: 비 고
B25: 효 율 파 트
C26: 효율업무 총괄
C27: [오현주]
C30: 효율업무1
C31: [이성진]
C34: 효율업무2
C35: [송관석]
C38: 일근현장운전원
C39: [최수민]
C42: 구매∙행정업무
B45: 운 전 파 트 | C45: Day 근무조 | D45: 1. Fly Ash Silo Wet Unloader측 상판 개방요청 | J45: TM 발행
C46: 1 | D46: 2. [TM작업]#1 Soot Blower #9 정비완료(Cam 고정핀 체결)
C47: =IF(C46=1,"[조용환+]",IF(C46=2,"[한만석+]",IF(C46=3,"[남정현+]",IF(C46=4,"[김광표+]","???")))) -> [조용환+] | D47: 3. [TM작업] Atomizer #A~C Duplex Filter Cleaning 완료
D48: 4. 07:10 #2 Limestone 입고관련
D49: - 하역 Line 막힘 추정되어 1호기 입고 실시
D50: - 하역 Line 음압 상태 및 상부 Vent Fan 상태 양호하여 추후 입고시 확인 요망
D51: 5. #2 Bed Ash Arm Roll Box 교체 완료
D52: 6. [TM작업] #2 Bio Screw Feeder #B Chain 장력 조정 완료
D53: 7. [TM작업]#2 Bed Ash BE-603 To Bed Ash Silo Inlet Fabric Chute 손상 보강작업 완료
D54: 8. [TM작업] #2 Soot Blower #2 Gland Tightening 완료
D55: 9. 2호기 유기성 고형연료 Blower #B Pully 취부 완료
D56: 10. [TM 작업] Cooling Tower Rear Dry Wet Damper 동작 불량 관련 점검
D57: 11. TBN 3F HP Process Spray Leak(TM 기발행) 주변 안전띠 설치
...

Sheet 15
B2: 설비운영팀 일일 업무 현황
B3: ='14'!B3+1 -> 46280
B5: 1. 주요 전달 및 지시사항(TM회의 등등 Issue사항) : 팀장(◎대표님, ○부문장님, -팀장, *기타 지시사항)
B6: [TM회의]
B7: ○ 1,2호기 Limestone 사용량 편차 발생원인 정상적인 것인지 점검 요망[팀장+효율,운전]
B8: ○ 유기성고형연료 금주 수요일까지 설비 문제 해소 완료하고, 목~금요일 시운전 완료 요망. 10월1~7일사이에 김제 우분 2대 입고 계획중이며, 10월1일 포천축협 돈분 1대 입고 계획중. 10월 중순에 경기권 GS포턴, 영남권 남부발전, 호남권 여수 남동발전 등 3개권영 축분이용 클러스터 조성 MOU 체결 계획 중이므로 차질없이 준비 필요 [공통]
B9: ○ 미이용산림은 내년 4월1일부터 혼소하는것으로 운영계획에 반영하고[송관석], 미이용산림 혼소 위한 설비개선 약 15~20억 공사발주 준비요망 [기계팀]
B10: ○ 보이소 앱 자이E운영 직원들도 참여 가능하면 앱설치토록 하여 자이E 에서도 사용토록 할 것 [송관석]
B11: ○ 설비운영팀 운전파트 운전원 심화교육은 매월 마지막주 수요일 17시부터 시행 요망 [설비운영팀]. 10월부터 매주 목요일 부문장님 교육참석으로 수요일로 변경
B12: ○ 4주차 화요일 TM회의에는 자이E운영 기계팀장 및 전기제어팀장도 회의 참석, 짝수달 마지막주 화요일 발주처 및 자이E 직책자 모임 정례화 [참고]
B14: [설비운영팀]
B15: - 운전파트 운전원 심화교육 자료 대상자 신속히 자료 작성 요망 [운전파트 대상자]
B16: - 9월13~14일 1,2호기 석회석 사용량 편차발생은 유기성사용량 편차 이외 다른 원인 있으면 전화, 카톡 등 신속히 팀장 공유 요망 [공통]
B22: 2. 주요 업무 현황 | J22: 일일발전 운전현황작성
B23: □ 효율파트 업무일지 및 운전파트 주요사항
B24: 구분 | C24: 업무[정+부] | D24: 주요 업무(업무내용, Event, Issue사항 등) | J24: 비 고
B25: 효 율 파 트
C26: 효율업무 총괄
C27: [오현주]
C30: 효율업무1
C31: [이성진]
C34: 효율업무2
C35: [송관석]
C38: 일근현장운전원
C39: [최수민]
C42: 구매∙행정업무
B45: 운 전 파 트 | C45: Day 근무조 | D45: 1. #1 BLR SDA Hopper Ash Grinder #A 고착 기동 불가 : 내부 이물질 끼임 추정 (차단기 OFF) | J45: TM발행
C46: 4 | D46: 2. 2층 전자기기실 CTH-201 압축기2 저압경보 Alarm발생 | J46: TM발행
