Workbook

Sheet 전기 Sheet
A1: Elec. Log Sheet
N2: 일 자 | R2: 2025. . .
N3: 설 비 운 영 팀 | R3: N/S
N5: 운전원 | R5: 파트장
B9: I T E M | G9: RATING | I9: UNIT | J9: 20:00 | M9: 00:00 | P9: 04:00 | S9: 비고
B10: GIS 154kV | E10: Gross Power | G10: - | I10: MW
D11: Volt | E11: 전압 | G11: <170 | I11: kV
D12: Current | E12: 전류 | G12: - | I12: A
B13: CB GIS | D13: CB03 | E13: Close/Open 상태 | G13: - | J13: Close / Open | M13: Close / Open | P13: Close / Open
D14: CB02 | E14: Close/Open 상태 | G14: - | J14: Close / Open | M14: Close / Open | P14: Close / Open
D15: CB01 | E15: Close/Open 상태 | G15: - | J15: Close / Open | M15: Close / Open | P15: Close / Open
D16: Volt | E16: 전압 | G16: <170 | I16: kV
D17: Current | E17: 전류 | G17: - | I17: A
B18: TR 6.9kV Incomming VCB | D18: GST | E18: 경보 | G18: N/A
E19: Oil Temp | G19: <105 | I19: ℃
D20: UAT | E20: 경보 | G20: N/A
E21: Oil Temp | G21: <105 | I21: ℃
D22: SUT | E22: 경보 | G22: N/A
E23: Oil Temp | G23: <105 | I23: ℃
D24: BBA BUS | E24: BBA01 GS002 | G24: - | J24: Close / Open | M24: Close / Open | P24: Close / Open
E25: 전압 | G25: 6.9~7.2 | I25: kV
E26: 전류 | G26: - | I26: A
D27: BBB BUS | E27: BBB01 GS002 | G27: - | J27: Close / Open | M27: Close / Open | P27: Close / Open
E28: 전압 | G28: 6.9~7.2 | I28: kV
E29: 전류 | G29: - | I29: A
B30: 6.9 kV Bus-Tie VCB | D30: Bus-Tie | E30: BBA01 GS005 Close/Open 상태 | G30: - | J30: Close / Open | M30: Close / Open | P30: Close / Open
E31: BBA01 GS004 Close/Open 상태 | G31: - | J31: Close / Open | M31: Close / Open | P31: Close / Open
B32: 460V Load Center | D32: BFA BUS | E32: 전압 | G32: - | I32: V
E33: 전류 | G33: 부하별 다름 | I33: A
D34: BFB BUS | E34: 전압 | G34: - | I34: V
E35: 전류 | G35: 부하별 다름 | I35: A
D36: BFC BUS | E36: 전압 | G36: - | I36: V
E37: 전류 | G37: 부하별 다름 | I37: A
D38: BFD BUS | E38: 전압 | G38: - | I38: V
E39: 전류 | G39: 부하별 다름 | I39: A
B40: Tr. DAILY LOG SHEET | D40: GST,UAT OIL TEMP | G40: <105 | I40: ℃
D41: SUT Oil/Winding TEMP | G41: <105 | I41: ℃
D42: GST,UAT LCP 경보 | G42: 양호(N) / 불량(A)
D43: SUT LCP 경보상태 | G43: 양호(N) / 불량(A)
D44: 변압기 AREA 누유상태 | G44: 양호(N) / 불량(A)
...

Sheet 야간 순찰 점검일지 양식
P1: 파트 선택
B2: 야간 순찰 점검일지 | G2: 파 트 장 | H2: 팀 장 | P2: 3
B4: 설비운영팀 | G4: 점검 일자 : 2023. 02. 01
B5: 시 간 | D5: 순찰자 | F5: 순찰 구역 | G5: 상 태 | H5: 특이 사항
B6: 1 | D6: =IF($P$2=1,랜덤!S7,IF($P$2=2,랜덤!T7,IF($P$2=3,랜덤!U7,IF($P$2=4,랜덤!V7,0)))) -> 이휘근 양영균 고병준 | F6: =랜덤!E2 -> Cooling Water Pump 전기실 점검 | G6: 양호
F7: =랜덤!E3 -> Bed Ash System 점검(3F) | G7: 양호
F8: =랜덤!E4 -> GIS Area 점검 | G8: 양호
F9: =랜덤!E5 -> PA/SA/ID Fan 점검(1F) | G9: 양호
F10: =랜덤!E6 -> Coal Daily Silo Air Canon 및 Silo 온도 점검(5F) | G10: 양호
F11: =랜덤!E7 -> ACWP, MCWP 점검 | G11: 양호
B12: 0.083333333 | D12: =IF($P$2=1,랜덤!S7,IF($P$2=2,랜덤!T7,IF($P$2=3,랜덤!U7,IF($P$2=4,랜덤!V7,0)))) -> 이휘근 양영균 고병준 | F12: =랜덤!E7 -> ACWP, MCWP 점검 | G12: 양호
F13: =랜덤!E8 -> 지하 HVAC Room 공조기 및 Sump Pump 점검 | G13: 양호
F14: =랜덤!E9 -> Drain To CCFT 및 Flash Tank Area 점검 | G14: 양호
F15: =랜덤!E10 -> Spiess Valve(L,R) 점검(4F) | G15: 양호
F16: =랜덤!E11 -> Limestone Blower/Bed Ash System 점검(1F) | G16: 양호
F17: =랜덤!E13 -> TBN Vacuum Seal Water 상태 점검 | G17: 양호
B18: 0.16666667 | D18: =IF($P$2=1,랜덤!S7,IF($P$2=2,랜덤!T7,IF($P$2=3,랜덤!U7,IF($P$2=4,랜덤!V7,0)))) -> 이휘근 양영균 고병준 | F18: =랜덤!E12 -> Steam Drum 점검(7F) | G18: 양호
F19: =랜덤!E13 -> TBN Vacuum Seal Water 상태 점검 | G19: 양호
F20: =랜덤!E14 -> Bio Feeding System 점검(Dosing, Slewing ..)(5F) | G20: 양호
F21: =랜덤!E15 -> CCWP 점검 | G21: 양호
F22: =랜덤!E16 -> Demi WTR Pump 점검 | G22: 양호
F23: =랜덤!E19 -> BFP 및 Co2 Room 점검(1F) | G23: 양호
B24: 0.25 | D24: =IF($P$2=1,랜덤!S7,IF($P$2=2,랜덤!T7,IF($P$2=3,랜덤!U7,IF($P$2=4,랜덤!V7,0)))) -> 이휘근 양영균 고병준 | F24: =랜덤!E17 -> HP Process STM Line 점검 | G24: 양호
F25: =랜덤!E18 -> Sonic Horn 점검(7F~8F) | G25: 양호
F26: =랜덤!E19 -> BFP 및 Co2 Room 점검(1F) | G26: 양호
F27: =랜덤!E20 -> TBN 계측기 도압관 Leak 여부 점검 | G27: 양호
F28: =랜덤!E21 -> SUT/GST/UAT 점검 | G28: 양호
F29: 6.
B30: 비고
N31: s

Sheet 랜덤
A1: 장소 | B1: 순위 | K1: 난수
A2: =RANK(K2,$K$2:$K$90,0) -> 42 | B2: Chemical Tank Area 점검 | D2: 1 | E2: =VLOOKUP(D2,$A$2:$B$90,2,0) -> Cooling Water Pump 전기실 점검 | K2: =RAND() -> 0.53833017 | N2: F9를 눌러주세요!!!!
A3: =RANK(K3,$K$2:$K$90,0) -> 59 | B3: CVP 점검 | D3: 2 | E3: =VLOOKUP(D3,$A$2:$B$90,2,0) -> Bed Ash System 점검(3F) | K3: =RAND() -> 0.28745341
A4: =RANK(K4,$K$2:$K$90,0) -> 54 | B4: Deaerator 점검(6F) | D4: 3 | E4: =VLOOKUP(D4,$A$2:$B$90,2,0) -> GIS Area 점검 | K4: =RAND() -> 0.35190893
A5: =RANK(K5,$K$2:$K$90,0) -> 50 | B5: Cyclone Area 점검(6F) | D5: 4 | E5: =VLOOKUP(D5,$A$2:$B$90,2,0) -> PA/SA/ID Fan 점검(1F) | K5: =RAND() -> 0.44656783
A6: =RANK(K6,$K$2:$K$90,0) -> 68 | B6: TBN CV Oil Leak 여부 점검 | D6: 5 | E6: =VLOOKUP(D6,$A$2:$B$90,2,0) -> Coal Daily Silo Air Canon 및 Silo 온도 점검(5F) | K6: =RAND() -> 0.19225253 | S6: 1 | T6: 2 | U6: 3 | V6: 4
A7: =RANK(K7,$K$2:$K$90,0) -> 17 | B7: Sonic Horn 점검(7F~8F) | D7: 6 | E7: =VLOOKUP(D7,$A$2:$B$90,2,0) -> ACWP, MCWP 점검 | K7: =RAND() -> 0.81760051 | S7: 서철민 김민중 변정률 | T7: 김현상 김지우 이용수 | U7: 이휘근 양영균 고병준 | V7: 한동혁 고석훈 김태민
A8: =RANK(K8,$K$2:$K$90,0) -> 5 | B8: Coal Daily Silo Air Canon 및 Silo 온도 점검(5F) | D8: 7 | E8: =VLOOKUP(D8,$A$2:$B$90,2,0) -> 지하 HVAC Room 공조기 및 Sump Pump 점검 | K8: =RAND() -> 0.96876205
A9: =RANK(K9,$K$2:$K$90,0) -> 71 | B9: HP Bypass Valve 점검(6F) | D9: 8 | E9: =VLOOKUP(D9,$A$2:$B$90,2,0) -> Drain To CCFT 및 Flash Tank Area 점검 | K9: =RAND() -> 0.17526713
A10: =RANK(K10,$K$2:$K$90,0) -> 78 | B10: Bag Filter Room 점검(1F) | D10: 9 | E10: =VLOOKUP(D10,$A$2:$B$90,2,0) -> Spiess Valve(L,R) 점검(4F) | K10: =RAND() -> 0.11023203
A11: =RANK(K11,$K$2:$K$90,0) -> 41 | B11: CCWP 점검 | D11: 10 | E11: =VLOOKUP(D11,$A$2:$B$90,2,0) -> Limestone Blower/Bed Ash System 점검(1F) | K11: =RAND() -> 0.54238385
A12: =RANK(K12,$K$2:$K$90,0) -> 23 | B12: Cooling Tower Vaccum Pump Room 점검 | D12: 11 | E12: =VLOOKUP(D12,$A$2:$B$90,2,0) -> Steam Drum 점검(7F) | K12: =RAND() -> 0.74169022
A13: =RANK(K13,$K$2:$K$90,0) -> 10 | B13: Limestone Blower/Bed Ash System 점검(1F) | D13: 12 | E13: =VLOOKUP(D13,$A$2:$B$90,2,0) -> TBN Vacuum Seal Water 상태 점검 | K13: =RAND() -> 0.91186827
A14: =RANK(K14,$K$2:$K$90,0) -> 79 | B14: Cooling Water Pump Room 점검 | D14: 13 | E14: =VLOOKUP(D14,$A$2:$B$90,2,0) -> Bio Feeding System 점검(Dosing, Slewing ..)(5F) | K14: =RAND() -> 0.10676573
A15: =RANK(K15,$K$2:$K$90,0) -> 31 | B15: Fly Ash Silo Room 점검 | D15: 14 | E15: =VLOOKUP(D15,$A$2:$B$90,2,0) -> CCWP 점검 | K15: =RAND() -> 0.67955324
A16: =RANK(K16,$K$2:$K$90,0) -> 26 | B16: #6 Heater 점검(3F) | D16: 15 | E16: =VLOOKUP(D16,$A$2:$B$90,2,0) -> Demi WTR Pump 점검 | K16: =RAND() -> 0.70849833
A17: =RANK(K17,$K$2:$K$90,0) -> 56 | B17: Cyclone 상부 점검(7F) | D17: 16 | E17: =VLOOKUP(D17,$A$2:$B$90,2,0) -> HP Process STM Line 점검 | K17: =RAND() -> 0.30795032
A18: =RANK(K18,$K$2:$K$90,0) -> 1 | B18: Cooling Water Pump 전기실 점검 | D18: 17 | E18: =VLOOKUP(D18,$A$2:$B$90,2,0) -> Sonic Horn 점검(7F~8F) | K18: =RAND() -> 0.9894537
A19: =RANK(K19,$K$2:$K$90,0) -> 36 | B19: 제어실 및 전기실 점검 | D19: 18 | E19: =VLOOKUP(D19,$A$2:$B$90,2,0) -> BFP 및 Co2 Room 점검(1F) | K19: =RAND() -> 0.65705594
... A21: =RANK(K21,$K$2:$K$90,0) -> 63 | B21: Bio Screw Feeder, Hopper Bin 점검(4.5F) | D21: 20 | E21: =VLOOKUP(D21,$A$2:$B$90,2,0) -> SUT/GST/UAT 점검 | K21: =RAND() -> 0.23994008
A22: =RANK(K22,$K$2:$K$90,0) -> 75 | B22: 배관망 Trap 응축수 상태 점검 | K22: =RAND() -> 0.14006987
A23: =RANK(K23,$K$2:$K$90,0) -> 57 | B23: 정압실 점검 | K23: =RAND() -> 0.29756221
A24: =RANK(K24,$K$2:$K$90,0) -> 8 | B24: Drain To CCFT 및 Flash Tank Area 점검 | K24: =RAND() -> 0.94799926
A25: =RANK(K25,$K$2:$K$90,0) -> 15 | B25: Demi WTR Pump 점검 | K25: =RAND() -> 0.85796736
A26: =RANK(K26,$K$2:$K$90,0) -> 83 | B26: Condensate Make-Up Pump 점검 | K26: =RAND() -> 0.08714905
A27: =RANK(K27,$K$2:$K$90,0) -> 65 | B27: Feed WTR LCV 및 Seal Pot 하부 점검(3.5F) | K27: =RAND() -> 0.22779371
A28: =RANK(K28,$K$2:$K$90,0) -> 28 | B28: CCFT Drain Pump 점검 | K28: =RAND() -> 0.69444995
A29: =RANK(K29,$K$2:$K$90,0) -> 14 | B29: CCWP 점검 | K29: =RAND() -> 0.85938575
A30: =RANK(K30,$K$2:$K$90,0) -> 53 | B30: Bed Ash Cooler/Conveyor 점검(1F) | K30: =RAND() -> 0.38149994
A31: =RANK(K31,$K$2:$K$90,0) -> 72 | B31: Start-Up Burner 점검(3F) | K31: =RAND() -> 0.17399113
A32: =RANK(K32,$K$2:$K$90,0) -> 51 | B32: Wall Screw Feeder Chute 열화 점검(2.5F) | K32: =RAND() -> 0.44457323
A33: =RANK(K33,$K$2:$K$90,0) -> 6 | B33: ACWP, MCWP 점검 | K33: =RAND() -> 0.96584079
... A90: =RANK(K90,$K$2:$K$90,0) -> 44 | B90: TBN AVR Room 점검 | K90: =RAND() -> 0.52317344
